Workbook

Sheet summary
A1: test_suite | B1: total_wirelength | C1: crit_path_delay | D1: total_runtime | E1: Baseline Unroutes
A2: vtr_largest | B2: ='ratios'!F10 | C2: ='ratios'!I10 | D2: ='ratios'!K10 | E2: ='ratios'!D11
A3: artix_7 | B3: ='ratios'!F21 | C3: ='ratios'!I21 | D3: ='ratios'!K21 | E3: ='ratios'!D22
A4: titan | B4: ='ratios'!F47 | C4: ='ratios'!I47 | D4: ='ratios'!K47 | E4: ='ratios'!D48
A5: koios | B5: ='ratios'!F79 | C5: ='ratios'!I79 | D5: ='ratios'!K79 | E5: ='ratios'!D80
A6: titanium_s10 | B6: ='ratios'!F106 | C6: ='ratios'!I106 | D6: ='ratios'!K106 | E6: ='ratios'!D107
A7: z1000 | B7: ='ratios'!F119 | C7: ='ratios'!I119 | D7: ='ratios'!K119 | E7: ='ratios'!D120

Sheet ratios
A1: test_suite | B1: arch | C1: circuit | D1: post_fl_hpwl | E1: post_dp_hpwl | F1: total_wirelength | G1: post_fl_cpd | H1: post_dp_cpd | I1: crit_path_delay | J1: route_runtime | K1: total_runtime
A2: vtr_largest | B2: k6_frac_N10_frac_chain_mem32K_40nm.xml | C2: arm_core.blif | D2: =IF(OR('vtr_largest_ap'!H2=-1, 'vtr_largest_no_ap'!H2=-1), "", 'vtr_largest_ap'!F2/'vtr_largest_no_ap'!F2) | E2: =IF(OR('vtr_largest_ap'!H2=-1, 'vtr_largest_no_ap'!H2=-1), "", 'vtr_largest_ap'!G2/'vtr_largest_no_ap'!G2) | F2: =IF(OR('vtr_largest_ap'!H2=-1, 'vtr_largest_no_ap'!H2=-1), "", 'vtr_largest_ap'!H2/'vtr_largest_no_ap'!H2) | G2: =IF(OR('vtr_largest_ap'!H2=-1, 'vtr_largest_no_ap'!H2=-1), "", 'vtr_largest_ap'!J2/'vtr_largest_no_ap'!J2) | H2: =IF(OR('vtr_largest_ap'!H2=-1, 'vtr_largest_no_ap'!H2=-1), "", 'vtr_largest_ap'!K2/'vtr_largest_no_ap'!K2) | I2: =IF(OR('vtr_largest_ap'!H2=-1, 'vtr_largest_no_ap'!H2=-1), "", 'vtr_largest_ap'!L2/'vtr_largest_no_ap'!L2) | J2: =IF(OR('vtr_largest_ap'!H2=-1, 'vtr_largest_no_ap'!H2=-1), "", 'vtr_largest_ap'!AC2/'vtr_largest_no_ap'!AC2) | K2: =IF(OR('vtr_largest_ap'!H2=-1, 'vtr_largest_no_ap'!H2=-1), "", 'vtr_largest_ap'!AD2/'vtr_largest_no_ap'!AD2)
A3: vtr_largest | B3: k6_frac_N10_frac_chain_mem32K_40nm.xml | C3: bgm.blif | D3: =IF(OR('vtr_largest_ap'!H3=-1, 'vtr_largest_no_ap'!H3=-1), "", 'vtr_largest_ap'!F3/'vtr_largest_no_ap'!F3) | E3: =IF(OR('vtr_largest_ap'!H3=-1, 'vtr_largest_no_ap'!H3=-1), "", 'vtr_largest_ap'!G3/'vtr_largest_no_ap'!G3) | F3: =IF(OR('vtr_largest_ap'!H3=-1, 'vtr_largest_no_ap'!H3=-1), "", 'vtr_largest_ap'!H3/'vtr_largest_no_ap'!H3) | G3: =IF(OR('vtr_largest_ap'!H3=-1, 'vtr_largest_no_ap'!H3=-1), "", 'vtr_largest_ap'!J3/'vtr_largest_no_ap'!J3) | H3: =IF(OR('vtr_largest_ap'!H3=-1, 'vtr_largest_no_ap'!H3=-1), "", 'vtr_largest_ap'!K3/'vtr_largest_no_ap'!K3) | I3: =IF(OR('vtr_largest_ap'!H3=-1, 'vtr_largest_no_ap'!H3=-1), "", 'vtr_largest_ap'!L3/'vtr_largest_no_ap'!L3) | J3: =IF(OR('vtr_largest_ap'!H3=-1, 'vtr_largest_no_ap'!H3=-1), "", 'vtr_largest_ap'!AC3/'vtr_largest_no_ap'!AC3) | K3: =IF(OR('vtr_largest_ap'!H3=-1, 'vtr_largest_no_ap'!H3=-1), "", 'vtr_largest_ap'!AD3/'vtr_largest_no_ap'!AD3)
A4: vtr_largest | B4: k6_frac_N10_frac_chain_mem32K_40nm.xml | C4: stereovision0.blif | D4: =IF(OR('vtr_largest_ap'!H4=-1, 'vtr_largest_no_ap'!H4=-1), "", 'vtr_largest_ap'!F4/'vtr_largest_no_ap'!F4) | E4: =IF(OR('vtr_largest_ap'!H4=-1, 'vtr_largest_no_ap'!H4=-1), "", 'vtr_largest_ap'!G4/'vtr_largest_no_ap'!G4) | F4: =IF(OR('vtr_largest_ap'!H4=-1, 'vtr_largest_no_ap'!H4=-1), "", 'vtr_largest_ap'!H4/'vtr_largest_no_ap'!H4) | G4: =IF(OR('vtr_largest_ap'!H4=-1, 'vtr_largest_no_ap'!H4=-1), "", 'vtr_largest_ap'!J4/'vtr_largest_no_ap'!J4) | H4: =IF(OR('vtr_largest_ap'!H4=-1, 'vtr_largest_no_ap'!H4=-1), "", 'vtr_largest_ap'!K4/'vtr_largest_no_ap'!K4) | I4: =IF(OR('vtr_largest_ap'!H4=-1, 'vtr_largest_no_ap'!H4=-1), "", 'vtr_largest_ap'!L4/'vtr_largest_no_ap'!L4) | J4: =IF(OR('vtr_largest_ap'!H4=-1, 'vtr_largest_no_ap'!H4=-1), "", 'vtr_largest_ap'!AC4/'vtr_largest_no_ap'!AC4) | K4: =IF(OR('vtr_largest_ap'!H4=-1, 'vtr_largest_no_ap'!H4=-1), "", 'vtr_largest_ap'!AD4/'vtr_largest_no_ap'!AD4)
A5: vtr_largest | B5: k6_frac_N10_frac_chain_mem32K_40nm.xml | C5: stereovision1.blif | D5: =IF(OR('vtr_largest_ap'!H5=-1, 'vtr_largest_no_ap'!H5=-1), "", 'vtr_largest_ap'!F5/'vtr_largest_no_ap'!F5) | E5: =IF(OR('vtr_largest_ap'!H5=-1, 'vtr_largest_no_ap'!H5=-1), "", 'vtr_largest_ap'!G5/'vtr_largest_no_ap'!G5) | F5: =IF(OR('vtr_largest_ap'!H5=-1, 'vtr_largest_no_ap'!H5=-1), "", 'vtr_largest_ap'!H5/'vtr_largest_no_ap'!H5) | G5: =IF(OR('vtr_largest_ap'!H5=-1, 'vtr_largest_no_ap'!H5=-1), "", 'vtr_largest_ap'!J5/'vtr_largest_no_ap'!J5) | H5: =IF(OR('vtr_largest_ap'!H5=-1, 'vtr_largest_no_ap'!H5=-1), "", 'vtr_largest_ap'!K5/'vtr_largest_no_ap'!K5) | I5: =IF(OR('vtr_largest_ap'!H5=-1, 'vtr_largest_no_ap'!H5=-1), "", 'vtr_largest_ap'!L5/'vtr_largest_no_ap'!L5) | J5: =IF(OR('vtr_largest_ap'!H5=-1, 'vtr_largest_no_ap'!H5=-1), "", 'vtr_largest_ap'!AC5/'vtr_largest_no_ap'!AC5) | K5: =IF(OR('vtr_largest_ap'!H5=-1, 'vtr_largest_no_ap'!H5=-1), "", 'vtr_largest_ap'!AD5/'vtr_largest_no_ap'!AD5)
A6: vtr_largest | B6: k6_frac_N10_frac_chain_mem32K_40nm.xml | C6: stereovision2.blif | D6: =IF(OR('vtr_largest_ap'!H6=-1, 'vtr_largest_no_ap'!H6=-1), "", 'vtr_largest_ap'!F6/'vtr_largest_no_ap'!F6) | E6: =IF(OR('vtr_largest_ap'!H6=-1, 'vtr_largest_no_ap'!H6=-1), "", 'vtr_largest_ap'!G6/'vtr_largest_no_ap'!G6) | F6: =IF(OR('vtr_largest_ap'!H6=-1, 'vtr_largest_no_ap'!H6=-1), "", 'vtr_largest_ap'!H6/'vtr_largest_no_ap'!H6) | G6: =IF(OR('vtr_largest_ap'!H6=-1, 'vtr_largest_no_ap'!H6=-1), "", 'vtr_largest_ap'!J6/'vtr_largest_no_ap'!J6) | H6: =IF(OR('vtr_largest_ap'!H6=-1, 'vtr_largest_no_ap'!H6=-1), "", 'vtr_largest_ap'!K6/'vtr_largest_no_ap'!K6) | I6: =IF(OR('vtr_largest_ap'!H6=-1, 'vtr_largest_no_ap'!H6=-1), "", 'vtr_largest_ap'!L6/'vtr_largest_no_ap'!L6) | J6: =IF(OR('vtr_largest_ap'!H6=-1, 'vtr_largest_no_ap'!H6=-1), "", 'vtr_largest_ap'!AC6/'vtr_largest_no_ap'!AC6) | K6: =IF(OR('vtr_largest_ap'!H6=-1, 'vtr_largest_no_ap'!H6=-1), "", 'vtr_largest_ap'!AD6/'vtr_largest_no_ap'!AD6)
A7: vtr_largest | B7: k6_frac_N10_frac_chain_mem32K_40nm.xml | C7: LU8PEEng.blif | D7: =IF(OR('vtr_largest_ap'!H7=-1, 'vtr_largest_no_ap'!H7=-1), "", 'vtr_largest_ap'!F7/'vtr_largest_no_ap'!F7) | E7: =IF(OR('vtr_largest_ap'!H7=-1, 'vtr_largest_no_ap'!H7=-1), "", 'vtr_largest_ap'!G7/'vtr_largest_no_ap'!G7) | F7: =IF(OR('vtr_largest_ap'!H7=-1, 'vtr_largest_no_ap'!H7=-1), "", 'vtr_largest_ap'!H7/'vtr_largest_no_ap'!H7) | G7: =IF(OR('vtr_largest_ap'!H7=-1, 'vtr_largest_no_ap'!H7=-1), "", 'vtr_largest_ap'!J7/'vtr_largest_no_ap'!J7) | H7: =IF(OR('vtr_largest_ap'!H7=-1, 'vtr_largest_no_ap'!H7=-1), "", 'vtr_largest_ap'!K7/'vtr_largest_no_ap'!K7) | I7: =IF(OR('vtr_largest_ap'!H7=-1, 'vtr_largest_no_ap'!H7=-1), "", 'vtr_largest_ap'!L7/'vtr_largest_no_ap'!L7) | J7: =IF(OR('vtr_largest_ap'!H7=-1, 'vtr_largest_no_ap'!H7=-1), "", 'vtr_largest_ap'!AC7/'vtr_largest_no_ap'!AC7) | K7: =IF(OR('vtr_largest_ap'!H7=-1, 'vtr_largest_no_ap'!H7=-1), "", 'vtr_largest_ap'!AD7/'vtr_largest_no_ap'!AD7)
A8: vtr_largest | B8: k6_frac_N10_frac_chain_mem32K_40nm.xml | C8: LU32PEEng.blif | D8: =IF(OR('vtr_largest_ap'!H8=-1, 'vtr_largest_no_ap'!H8=-1), "", 'vtr_largest_ap'!F8/'vtr_largest_no_ap'!F8) | E8: =IF(OR('vtr_largest_ap'!H8=-1, 'vtr_largest_no_ap'!H8=-1), "", 'vtr_largest_ap'!G8/'vtr_largest_no_ap'!G8) | F8: =IF(OR('vtr_largest_ap'!H8=-1, 'vtr_largest_no_ap'!H8=-1), "", 'vtr_largest_ap'!H8/'vtr_largest_no_ap'!H8) | G8: =IF(OR('vtr_largest_ap'!H8=-1, 'vtr_largest_no_ap'!H8=-1), "", 'vtr_largest_ap'!J8/'vtr_largest_no_ap'!J8) | H8: =IF(OR('vtr_largest_ap'!H8=-1, 'vtr_largest_no_ap'!H8=-1), "", 'vtr_largest_ap'!K8/'vtr_largest_no_ap'!K8) | I8: =IF(OR('vtr_largest_ap'!H8=-1, 'vtr_largest_no_ap'!H8=-1), "", 'vtr_largest_ap'!L8/'vtr_largest_no_ap'!L8) | J8: =IF(OR('vtr_largest_ap'!H8=-1, 'vtr_largest_no_ap'!H8=-1), "", 'vtr_largest_ap'!AC8/'vtr_largest_no_ap'!AC8) | K8: =IF(OR('vtr_largest_ap'!H8=-1, 'vtr_largest_no_ap'!H8=-1), "", 'vtr_largest_ap'!AD8/'vtr_largest_no_ap'!AD8)
A9: vtr_largest | B9: k6_frac_N10_frac_chain_mem32K_40nm.xml | C9: mcml.blif | D9: =IF(OR('vtr_largest_ap'!H9=-1, 'vtr_largest_no_ap'!H9=-1), "", 'vtr_largest_ap'!F9/'vtr_largest_no_ap'!F9) | E9: =IF(OR('vtr_largest_ap'!H9=-1, 'vtr_largest_no_ap'!H9=-1), "", 'vtr_largest_ap'!G9/'vtr_largest_no_ap'!G9) | F9: =IF(OR('vtr_largest_ap'!H9=-1, 'vtr_largest_no_ap'!H9=-1), "", 'vtr_largest_ap'!H9/'vtr_largest_no_ap'!H9) | G9: =IF(OR('vtr_largest_ap'!H9=-1, 'vtr_largest_no_ap'!H9=-1), "", 'vtr_largest_ap'!J9/'vtr_largest_no_ap'!J9) | H9: =IF(OR('vtr_largest_ap'!H9=-1, 'vtr_largest_no_ap'!H9=-1), "", 'vtr_largest_ap'!K9/'vtr_largest_no_ap'!K9) | I9: =IF(OR('vtr_largest_ap'!H9=-1, 'vtr_largest_no_ap'!H9=-1), "", 'vtr_largest_ap'!L9/'vtr_largest_no_ap'!L9) | J9: =IF(OR('vtr_largest_ap'!H9=-1, 'vtr_largest_no_ap'!H9=-1), "", 'vtr_largest_ap'!AC9/'vtr_largest_no_ap'!AC9) | K9: =IF(OR('vtr_largest_ap'!H9=-1, 'vtr_largest_no_ap'!H9=-1), "", 'vtr_largest_ap'!AD9/'vtr_largest_no_ap'!AD9)
A10: vtr_largest | C10: GEOMEAN | D10: =GEOMEAN(D2:D9) | E10: =GEOMEAN(E2:E9) | F10: =GEOMEAN(F2:F9) | G10: =GEOMEAN(G2:G9) | H10: =GEOMEAN(H2:H9) | I10: =GEOMEAN(I2:I9) | J10: =GEOMEAN(J2:J9) | K10: =GEOMEAN(K2:K9)
A11: vtr_largest | C11: UNROUTES | D11: =8 - COUNT(F2:F9)
A13: artix_7 | B13: 7series_BRAM_DSP_carry.xml | C13: arm_core.blif | D13: =IF(OR('artix_7_ap'!H2=-1, 'artix_7_no_ap'!H2=-1), "", 'artix_7_ap'!F2/'artix_7_no_ap'!F2) | E13: =IF(OR('artix_7_ap'!H2=-1, 'artix_7_no_ap'!H2=-1), "", 'artix_7_ap'!G2/'artix_7_no_ap'!G2) | F13: =IF(OR('artix_7_ap'!H2=-1, 'artix_7_no_ap'!H2=-1), "", 'artix_7_ap'!H2/'artix_7_no_ap'!H2) | G13: =IF(OR('artix_7_ap'!H2=-1, 'artix_7_no_ap'!H2=-1), "", 'artix_7_ap'!J2/'artix_7_no_ap'!J2) | H13: =IF(OR('artix_7_ap'!H2=-1, 'artix_7_no_ap'!H2=-1), "", 'artix_7_ap'!K2/'artix_7_no_ap'!K2) | I13: =IF(OR('artix_7_ap'!H2=-1, 'artix_7_no_ap'!H2=-1), "", 'artix_7_ap'!L2/'artix_7_no_ap'!L2) | J13: =IF(OR('artix_7_ap'!H2=-1, 'artix_7_no_ap'!H2=-1), "", 'artix_7_ap'!AC2/'artix_7_no_ap'!AC2) | K13: =IF(OR('artix_7_ap'!H2=-1, 'artix_7_no_ap'!H2=-1), "", 'artix_7_ap'!AD2/'artix_7_no_ap'!AD2)
A14: artix_7 | B14: 7series_BRAM_DSP_carry.xml | C14: bgm.blif | D14: =IF(OR('artix_7_ap'!H3=-1, 'artix_7_no_ap'!H3=-1), "", 'artix_7_ap'!F3/'artix_7_no_ap'!F3) | E14: =IF(OR('artix_7_ap'!H3=-1, 'artix_7_no_ap'!H3=-1), "", 'artix_7_ap'!G3/'artix_7_no_ap'!G3) | F14: =IF(OR('artix_7_ap'!H3=-1, 'artix_7_no_ap'!H3=-1), "", 'artix_7_ap'!H3/'artix_7_no_ap'!H3) | G14: =IF(OR('artix_7_ap'!H3=-1, 'artix_7_no_ap'!H3=-1), "", 'artix_7_ap'!J3/'artix_7_no_ap'!J3) | H14: =IF(OR('artix_7_ap'!H3=-1, 'artix_7_no_ap'!H3=-1), "", 'artix_7_ap'!K3/'artix_7_no_ap'!K3) | I14: =IF(OR('artix_7_ap'!H3=-1, 'artix_7_no_ap'!H3=-1), "", 'artix_7_ap'!L3/'artix_7_no_ap'!L3) | J14: =IF(OR('artix_7_ap'!H3=-1, 'artix_7_no_ap'!H3=-1), "", 'artix_7_ap'!AC3/'artix_7_no_ap'!AC3) | K14: =IF(OR('artix_7_ap'!H3=-1, 'artix_7_no_ap'!H3=-1), "", 'artix_7_ap'!AD3/'artix_7_no_ap'!AD3)
A15: artix_7 | B15: 7series_BRAM_DSP_carry.xml | C15: stereovision0.blif | D15: =IF(OR('artix_7_ap'!H4=-1, 'artix_7_no_ap'!H4=-1), "", 'artix_7_ap'!F4/'artix_7_no_ap'!F4) | E15: =IF(OR('artix_7_ap'!H4=-1, 'artix_7_no_ap'!H4=-1), "", 'artix_7_ap'!G4/'artix_7_no_ap'!G4) | F15: =IF(OR('artix_7_ap'!H4=-1, 'artix_7_no_ap'!H4=-1), "", 'artix_7_ap'!H4/'artix_7_no_ap'!H4) | G15: =IF(OR('artix_7_ap'!H4=-1, 'artix_7_no_ap'!H4=-1), "", 'artix_7_ap'!J4/'artix_7_no_ap'!J4) | H15: =IF(OR('artix_7_ap'!H4=-1, 'artix_7_no_ap'!H4=-1), "", 'artix_7_ap'!K4/'artix_7_no_ap'!K4) | I15: =IF(OR('artix_7_ap'!H4=-1, 'artix_7_no_ap'!H4=-1), "", 'artix_7_ap'!L4/'artix_7_no_ap'!L4) | J15: =IF(OR('artix_7_ap'!H4=-1, 'artix_7_no_ap'!H4=-1), "", 'artix_7_ap'!AC4/'artix_7_no_ap'!AC4) | K15: =IF(OR('artix_7_ap'!H4=-1, 'artix_7_no_ap'!H4=-1), "", 'artix_7_ap'!AD4/'artix_7_no_ap'!AD4)
A16: artix_7 | B16: 7series_BRAM_DSP_carry.xml | C16: stereovision1.blif | D16: =IF(OR('artix_7_ap'!H5=-1, 'artix_7_no_ap'!H5=-1), "", 'artix_7_ap'!F5/'artix_7_no_ap'!F5) | E16: =IF(OR('artix_7_ap'!H5=-1, 'artix_7_no_ap'!H5=-1), "", 'artix_7_ap'!G5/'artix_7_no_ap'!G5) | F16: =IF(OR('artix_7_ap'!H5=-1, 'artix_7_no_ap'!H5=-1), "", 'artix_7_ap'!H5/'artix_7_no_ap'!H5) | G16: =IF(OR('artix_7_ap'!H5=-1, 'artix_7_no_ap'!H5=-1), "", 'artix_7_ap'!J5/'artix_7_no_ap'!J5) | H16: =IF(OR('artix_7_ap'!H5=-1, 'artix_7_no_ap'!H5=-1), "", 'artix_7_ap'!K5/'artix_7_no_ap'!K5) | I16: =IF(OR('artix_7_ap'!H5=-1, 'artix_7_no_ap'!H5=-1), "", 'artix_7_ap'!L5/'artix_7_no_ap'!L5) | J16: =IF(OR('artix_7_ap'!H5=-1, 'artix_7_no_ap'!H5=-1), "", 'artix_7_ap'!AC5/'artix_7_no_ap'!AC5) | K16: =IF(OR('artix_7_ap'!H5=-1, 'artix_7_no_ap'!H5=-1), "", 'artix_7_ap'!AD5/'artix_7_no_ap'!AD5)
A17: artix_7 | B17: 7series_BRAM_DSP_carry.xml | C17: stereovision2.blif | D17: =IF(OR('artix_7_ap'!H6=-1, 'artix_7_no_ap'!H6=-1), "", 'artix_7_ap'!F6/'artix_7_no_ap'!F6) | E17: =IF(OR('artix_7_ap'!H6=-1, 'artix_7_no_ap'!H6=-1), "", 'artix_7_ap'!G6/'artix_7_no_ap'!G6) | F17: =IF(OR('artix_7_ap'!H6=-1, 'artix_7_no_ap'!H6=-1), "", 'artix_7_ap'!H6/'artix_7_no_ap'!H6) | G17: =IF(OR('artix_7_ap'!H6=-1, 'artix_7_no_ap'!H6=-1), "", 'artix_7_ap'!J6/'artix_7_no_ap'!J6) | H17: =IF(OR('artix_7_ap'!H6=-1, 'artix_7_no_ap'!H6=-1), "", 'artix_7_ap'!K6/'artix_7_no_ap'!K6) | I17: =IF(OR('artix_7_ap'!H6=-1, 'artix_7_no_ap'!H6=-1), "", 'artix_7_ap'!L6/'artix_7_no_ap'!L6) | J17: =IF(OR('artix_7_ap'!H6=-1, 'artix_7_no_ap'!H6=-1), "", 'artix_7_ap'!AC6/'artix_7_no_ap'!AC6) | K17: =IF(OR('artix_7_ap'!H6=-1, 'artix_7_no_ap'!H6=-1), "", 'artix_7_ap'!AD6/'artix_7_no_ap'!AD6)
A18: artix_7 | B18: 7series_BRAM_DSP_carry.xml | C18: LU8PEEng.blif | D18: =IF(OR('artix_7_ap'!H7=-1, 'artix_7_no_ap'!H7=-1), "", 'artix_7_ap'!F7/'artix_7_no_ap'!F7) | E18: =IF(OR('artix_7_ap'!H7=-1, 'artix_7_no_ap'!H7=-1), "", 'artix_7_ap'!G7/'artix_7_no_ap'!G7) | F18: =IF(OR('artix_7_ap'!H7=-1, 'artix_7_no_ap'!H7=-1), "", 'artix_7_ap'!H7/'artix_7_no_ap'!H7) | G18: =IF(OR('artix_7_ap'!H7=-1, 'artix_7_no_ap'!H7=-1), "", 'artix_7_ap'!J7/'artix_7_no_ap'!J7) | H18: =IF(OR('artix_7_ap'!H7=-1, 'artix_7_no_ap'!H7=-1), "", 'artix_7_ap'!K7/'artix_7_no_ap'!K7) | I18: =IF(OR('artix_7_ap'!H7=-1, 'artix_7_no_ap'!H7=-1), "", 'artix_7_ap'!L7/'artix_7_no_ap'!L7) | J18: =IF(OR('artix_7_ap'!H7=-1, 'artix_7_no_ap'!H7=-1), "", 'artix_7_ap'!AC7/'artix_7_no_ap'!AC7) | K18: =IF(OR('artix_7_ap'!H7=-1, 'artix_7_no_ap'!H7=-1), "", 'artix_7_ap'!AD7/'artix_7_no_ap'!AD7)
A19: artix_7 | B19: 7series_BRAM_DSP_carry.xml | C19: LU32PEEng.blif | D19: =IF(OR('artix_7_ap'!H8=-1, 'artix_7_no_ap'!H8=-1), "", 'artix_7_ap'!F8/'artix_7_no_ap'!F8) | E19: =IF(OR('artix_7_ap'!H8=-1, 'artix_7_no_ap'!H8=-1), "", 'artix_7_ap'!G8/'artix_7_no_ap'!G8) | F19: =IF(OR('artix_7_ap'!H8=-1, 'artix_7_no_ap'!H8=-1), "", 'artix_7_ap'!H8/'artix_7_no_ap'!H8) | G19: =IF(OR('artix_7_ap'!H8=-1, 'artix_7_no_ap'!H8=-1), "", 'artix_7_ap'!J8/'artix_7_no_ap'!J8) | H19: =IF(OR('artix_7_ap'!H8=-1, 'artix_7_no_ap'!H8=-1), "", 'artix_7_ap'!K8/'artix_7_no_ap'!K8) | I19: =IF(OR('artix_7_ap'!H8=-1, 'artix_7_no_ap'!H8=-1), "", 'artix_7_ap'!L8/'artix_7_no_ap'!L8) | J19: =IF(OR('artix_7_ap'!H8=-1, 'artix_7_no_ap'!H8=-1), "", 'artix_7_ap'!AC8/'artix_7_no_ap'!AC8) | K19: =IF(OR('artix_7_ap'!H8=-1, 'artix_7_no_ap'!H8=-1), "", 'artix_7_ap'!AD8/'artix_7_no_ap'!AD8)
A20: artix_7 | B20: 7series_BRAM_DSP_carry.xml | C20: mcml.blif | D20: =IF(OR('artix_7_ap'!H9=-1, 'artix_7_no_ap'!H9=-1), "", 'artix_7_ap'!F9/'artix_7_no_ap'!F9) | E20: =IF(OR('artix_7_ap'!H9=-1, 'artix_7_no_ap'!H9=-1), "", 'artix_7_ap'!G9/'artix_7_no_ap'!G9) | F20: =IF(OR('artix_7_ap'!H9=-1, 'artix_7_no_ap'!H9=-1), "", 'artix_7_ap'!H9/'artix_7_no_ap'!H9) | G20: =IF(OR('artix_7_ap'!H9=-1, 'artix_7_no_ap'!H9=-1), "", 'artix_7_ap'!J9/'artix_7_no_ap'!J9) | H20: =IF(OR('artix_7_ap'!H9=-1, 'artix_7_no_ap'!H9=-1), "", 'artix_7_ap'!K9/'artix_7_no_ap'!K9) | I20: =IF(OR('artix_7_ap'!H9=-1, 'artix_7_no_ap'!H9=-1), "", 'artix_7_ap'!L9/'artix_7_no_ap'!L9) | J20: =IF(OR('artix_7_ap'!H9=-1, 'artix_7_no_ap'!H9=-1), "", 'artix_7_ap'!AC9/'artix_7_no_ap'!AC9) | K20: =IF(OR('artix_7_ap'!H9=-1, 'artix_7_no_ap'!H9=-1), "", 'artix_7_ap'!AD9/'artix_7_no_ap'!AD9)
A21: artix_7 | C21: GEOMEAN | D21: =GEOMEAN(D13:D20) | E21: =GEOMEAN(E13:E20) | F21: =GEOMEAN(F13:F20) | G21: =GEOMEAN(G13:G20) | H21: =GEOMEAN(H13:H20) | I21: =GEOMEAN(I13:I20) | J21: =GEOMEAN(J13:J20) | K21: =GEOMEAN(K13:K20)
A22: artix_7 | C22: UNROUTES | D22: =8 - COUNT(F13:F20)
A24: titan | B24: stratixiv_arch.timing.xml | C24: LU230_stratixiv_arch_timing.blif | D24: =IF(OR('titan_ap'!H2=-1, 'titan_no_ap'!H2=-1), "", 'titan_ap'!F2/'titan_no_ap'!F2) | E24: =IF(OR('titan_ap'!H2=-1, 'titan_no_ap'!H2=-1), "", 'titan_ap'!G2/'titan_no_ap'!G2) | F24: =IF(OR('titan_ap'!H2=-1, 'titan_no_ap'!H2=-1), "", 'titan_ap'!H2/'titan_no_ap'!H2) | G24: =IF(OR('titan_ap'!H2=-1, 'titan_no_ap'!H2=-1), "", 'titan_ap'!J2/'titan_no_ap'!J2) | H24: =IF(OR('titan_ap'!H2=-1, 'titan_no_ap'!H2=-1), "", 'titan_ap'!K2/'titan_no_ap'!K2) | I24: =IF(OR('titan_ap'!H2=-1, 'titan_no_ap'!H2=-1), "", 'titan_ap'!L2/'titan_no_ap'!L2) | J24: =IF(OR('titan_ap'!H2=-1, 'titan_no_ap'!H2=-1), "", 'titan_ap'!AC2/'titan_no_ap'!AC2) | K24: =IF(OR('titan_ap'!H2=-1, 'titan_no_ap'!H2=-1), "", 'titan_ap'!AD2/'titan_no_ap'!AD2)
A25: titan | B25: stratixiv_arch.timing.xml | C25: LU_Network_stratixiv_arch_timing.blif | D25: =IF(OR('titan_ap'!H3=-1, 'titan_no_ap'!H3=-1), "", 'titan_ap'!F3/'titan_no_ap'!F3) | E25: =IF(OR('titan_ap'!H3=-1, 'titan_no_ap'!H3=-1), "", 'titan_ap'!G3/'titan_no_ap'!G3) | F25: =IF(OR('titan_ap'!H3=-1, 'titan_no_ap'!H3=-1), "", 'titan_ap'!H3/'titan_no_ap'!H3) | G25: =IF(OR('titan_ap'!H3=-1, 'titan_no_ap'!H3=-1), "", 'titan_ap'!J3/'titan_no_ap'!J3) | H25: =IF(OR('titan_ap'!H3=-1, 'titan_no_ap'!H3=-1), "", 'titan_ap'!K3/'titan_no_ap'!K3) | I25: =IF(OR('titan_ap'!H3=-1, 'titan_no_ap'!H3=-1), "", 'titan_ap'!L3/'titan_no_ap'!L3) | J25: =IF(OR('titan_ap'!H3=-1, 'titan_no_ap'!H3=-1), "", 'titan_ap'!AC3/'titan_no_ap'!AC3) | K25: =IF(OR('titan_ap'!H3=-1, 'titan_no_ap'!H3=-1), "", 'titan_ap'!AD3/'titan_no_ap'!AD3)
A26: titan | B26: stratixiv_arch.timing.xml | C26: SLAM_spheric_stratixiv_arch_timing.blif | D26: =IF(OR('titan_ap'!H4=-1, 'titan_no_ap'!H4=-1), "", 'titan_ap'!F4/'titan_no_ap'!F4) | E26: =IF(OR('titan_ap'!H4=-1, 'titan_no_ap'!H4=-1), "", 'titan_ap'!G4/'titan_no_ap'!G4) | F26: =IF(OR('titan_ap'!H4=-1, 'titan_no_ap'!H4=-1), "", 'titan_ap'!H4/'titan_no_ap'!H4) | G26: =IF(OR('titan_ap'!H4=-1, 'titan_no_ap'!H4=-1), "", 'titan_ap'!J4/'titan_no_ap'!J4) | H26: =IF(OR('titan_ap'!H4=-1, 'titan_no_ap'!H4=-1), "", 'titan_ap'!K4/'titan_no_ap'!K4) | I26: =IF(OR('titan_ap'!H4=-1, 'titan_no_ap'!H4=-1), "", 'titan_ap'!L4/'titan_no_ap'!L4) | J26: =IF(OR('titan_ap'!H4=-1, 'titan_no_ap'!H4=-1), "", 'titan_ap'!AC4/'titan_no_ap'!AC4) | K26: =IF(OR('titan_ap'!H4=-1, 'titan_no_ap'!H4=-1), "", 'titan_ap'!AD4/'titan_no_ap'!AD4)
A27: titan | B27: stratixiv_arch.timing.xml | C27: bitcoin_miner_stratixiv_arch_timing.blif | D27: =IF(OR('titan_ap'!H5=-1, 'titan_no_ap'!H5=-1), "", 'titan_ap'!F5/'titan_no_ap'!F5) | E27: =IF(OR('titan_ap'!H5=-1, 'titan_no_ap'!H5=-1), "", 'titan_ap'!G5/'titan_no_ap'!G5) | F27: =IF(OR('titan_ap'!H5=-1, 'titan_no_ap'!H5=-1), "", 'titan_ap'!H5/'titan_no_ap'!H5) | G27: =IF(OR('titan_ap'!H5=-1, 'titan_no_ap'!H5=-1), "", 'titan_ap'!J5/'titan_no_ap'!J5) | H27: =IF(OR('titan_ap'!H5=-1, 'titan_no_ap'!H5=-1), "", 'titan_ap'!K5/'titan_no_ap'!K5) | I27: =IF(OR('titan_ap'!H5=-1, 'titan_no_ap'!H5=-1), "", 'titan_ap'!L5/'titan_no_ap'!L5) | J27: =IF(OR('titan_ap'!H5=-1, 'titan_no_ap'!H5=-1), "", 'titan_ap'!AC5/'titan_no_ap'!AC5) | K27: =IF(OR('titan_ap'!H5=-1, 'titan_no_ap'!H5=-1), "", 'titan_ap'!AD5/'titan_no_ap'!AD5)
A28: titan | B28: stratixiv_arch.timing.xml | C28: bitonic_mesh_stratixiv_arch_timing.blif | D28: =IF(OR('titan_ap'!H6=-1, 'titan_no_ap'!H6=-1), "", 'titan_ap'!F6/'titan_no_ap'!F6) | E28: =IF(OR('titan_ap'!H6=-1, 'titan_no_ap'!H6=-1), "", 'titan_ap'!G6/'titan_no_ap'!G6) | F28: =IF(OR('titan_ap'!H6=-1, 'titan_no_ap'!H6=-1), "", 'titan_ap'!H6/'titan_no_ap'!H6) | G28: =IF(OR('titan_ap'!H6=-1, 'titan_no_ap'!H6=-1), "", 'titan_ap'!J6/'titan_no_ap'!J6) | H28: =IF(OR('titan_ap'!H6=-1, 'titan_no_ap'!H6=-1), "", 'titan_ap'!K6/'titan_no_ap'!K6) | I28: =IF(OR('titan_ap'!H6=-1, 'titan_no_ap'!H6=-1), "", 'titan_ap'!L6/'titan_no_ap'!L6) | J28: =IF(OR('titan_ap'!H6=-1, 'titan_no_ap'!H6=-1), "", 'titan_ap'!AC6/'titan_no_ap'!AC6) | K28: =IF(OR('titan_ap'!H6=-1, 'titan_no_ap'!H6=-1), "", 'titan_ap'!AD6/'titan_no_ap'!AD6)
A29: titan | B29: stratixiv_arch.timing.xml | C29: cholesky_bdti_stratixiv_arch_timing.blif | D29: =IF(OR('titan_ap'!H7=-1, 'titan_no_ap'!H7=-1), "", 'titan_ap'!F7/'titan_no_ap'!F7) | E29: =IF(OR('titan_ap'!H7=-1, 'titan_no_ap'!H7=-1), "", 'titan_ap'!G7/'titan_no_ap'!G7) | F29: =IF(OR('titan_ap'!H7=-1, 'titan_no_ap'!H7=-1), "", 'titan_ap'!H7/'titan_no_ap'!H7) | G29: =IF(OR('titan_ap'!H7=-1, 'titan_no_ap'!H7=-1), "", 'titan_ap'!J7/'titan_no_ap'!J7) | H29: =IF(OR('titan_ap'!H7=-1, 'titan_no_ap'!H7=-1), "", 'titan_ap'!K7/'titan_no_ap'!K7) | I29: =IF(OR('titan_ap'!H7=-1, 'titan_no_ap'!H7=-1), "", 'titan_ap'!L7/'titan_no_ap'!L7) | J29: =IF(OR('titan_ap'!H7=-1, 'titan_no_ap'!H7=-1), "", 'titan_ap'!AC7/'titan_no_ap'!AC7) | K29: =IF(OR('titan_ap'!H7=-1, 'titan_no_ap'!H7=-1), "", 'titan_ap'!AD7/'titan_no_ap'!AD7)
A30: titan | B30: stratixiv_arch.timing.xml | C30: cholesky_mc_stratixiv_arch_timing.blif | D30: =IF(OR('titan_ap'!H8=-1, 'titan_no_ap'!H8=-1), "", 'titan_ap'!F8/'titan_no_ap'!F8) | E30: =IF(OR('titan_ap'!H8=-1, 'titan_no_ap'!H8=-1), "", 'titan_ap'!G8/'titan_no_ap'!G8) | F30: =IF(OR('titan_ap'!H8=-1, 'titan_no_ap'!H8=-1), "", 'titan_ap'!H8/'titan_no_ap'!H8) | G30: =IF(OR('titan_ap'!H8=-1, 'titan_no_ap'!H8=-1), "", 'titan_ap'!J8/'titan_no_ap'!J8) | H30: =IF(OR('titan_ap'!H8=-1, 'titan_no_ap'!H8=-1), "", 'titan_ap'!K8/'titan_no_ap'!K8) | I30: =IF(OR('titan_ap'!H8=-1, 'titan_no_ap'!H8=-1), "", 'titan_ap'!L8/'titan_no_ap'!L8) | J30: =IF(OR('titan_ap'!H8=-1, 'titan_no_ap'!H8=-1), "", 'titan_ap'!AC8/'titan_no_ap'!AC8) | K30: =IF(OR('titan_ap'!H8=-1, 'titan_no_ap'!H8=-1), "", 'titan_ap'!AD8/'titan_no_ap'!AD8)
A31: titan | B31: stratixiv_arch.timing.xml | C31: dart_stratixiv_arch_timing.blif | D31: =IF(OR('titan_ap'!H9=-1, 'titan_no_ap'!H9=-1), "", 'titan_ap'!F9/'titan_no_ap'!F9) | E31: =IF(OR('titan_ap'!H9=-1, 'titan_no_ap'!H9=-1), "", 'titan_ap'!G9/'titan_no_ap'!G9) | F31: =IF(OR('titan_ap'!H9=-1, 'titan_no_ap'!H9=-1), "", 'titan_ap'!H9/'titan_no_ap'!H9) | G31: =IF(OR('titan_ap'!H9=-1, 'titan_no_ap'!H9=-1), "", 'titan_ap'!J9/'titan_no_ap'!J9) | H31: =IF(OR('titan_ap'!H9=-1, 'titan_no_ap'!H9=-1), "", 'titan_ap'!K9/'titan_no_ap'!K9) | I31: =IF(OR('titan_ap'!H9=-1, 'titan_no_ap'!H9=-1), "", 'titan_ap'!L9/'titan_no_ap'!L9) | J31: =IF(OR('titan_ap'!H9=-1, 'titan_no_ap'!H9=-1), "", 'titan_ap'!AC9/'titan_no_ap'!AC9) | K31: =IF(OR('titan_ap'!H9=-1, 'titan_no_ap'!H9=-1), "", 'titan_ap'!AD9/'titan_no_ap'!AD9)
A32: titan | B32: stratixiv_arch.timing.xml | C32: denoise_stratixiv_arch_timing.blif | D32: =IF(OR('titan_ap'!H10=-1, 'titan_no_ap'!H10=-1), "", 'titan_ap'!F10/'titan_no_ap'!F10) | E32: =IF(OR('titan_ap'!H10=-1, 'titan_no_ap'!H10=-1), "", 'titan_ap'!G10/'titan_no_ap'!G10) | F32: =IF(OR('titan_ap'!H10=-1, 'titan_no_ap'!H10=-1), "", 'titan_ap'!H10/'titan_no_ap'!H10) | G32: =IF(OR('titan_ap'!H10=-1, 'titan_no_ap'!H10=-1), "", 'titan_ap'!J10/'titan_no_ap'!J10) | H32: =IF(OR('titan_ap'!H10=-1, 'titan_no_ap'!H10=-1), "", 'titan_ap'!K10/'titan_no_ap'!K10) | I32: =IF(OR('titan_ap'!H10=-1, 'titan_no_ap'!H10=-1), "", 'titan_ap'!L10/'titan_no_ap'!L10) | J32: =IF(OR('titan_ap'!H10=-1, 'titan_no_ap'!H10=-1), "", 'titan_ap'!AC10/'titan_no_ap'!AC10) | K32: =IF(OR('titan_ap'!H10=-1, 'titan_no_ap'!H10=-1), "", 'titan_ap'!AD10/'titan_no_ap'!AD10)
A33: titan | B33: stratixiv_arch.timing.xml | C33: des90_stratixiv_arch_timing.blif | D33: =IF(OR('titan_ap'!H11=-1, 'titan_no_ap'!H11=-1), "", 'titan_ap'!F11/'titan_no_ap'!F11) | E33: =IF(OR('titan_ap'!H11=-1, 'titan_no_ap'!H11=-1), "", 'titan_ap'!G11/'titan_no_ap'!G11) | F33: =IF(OR('titan_ap'!H11=-1, 'titan_no_ap'!H11=-1), "", 'titan_ap'!H11/'titan_no_ap'!H11) | G33: =IF(OR('titan_ap'!H11=-1, 'titan_no_ap'!H11=-1), "", 'titan_ap'!J11/'titan_no_ap'!J11) | H33: =IF(OR('titan_ap'!H11=-1, 'titan_no_ap'!H11=-1), "", 'titan_ap'!K11/'titan_no_ap'!K11) | I33: =IF(OR('titan_ap'!H11=-1, 'titan_no_ap'!H11=-1), "", 'titan_ap'!L11/'titan_no_ap'!L11) | J33: =IF(OR('titan_ap'!H11=-1, 'titan_no_ap'!H11=-1), "", 'titan_ap'!AC11/'titan_no_ap'!AC11) | K33: =IF(OR('titan_ap'!H11=-1, 'titan_no_ap'!H11=-1), "", 'titan_ap'!AD11/'titan_no_ap'!AD11)
A34: titan | B34: stratixiv_arch.timing.xml | C34: directrf_stratixiv_arch_timing.blif | D34: =IF(OR('titan_ap'!H12=-1, 'titan_no_ap'!H12=-1), "", 'titan_ap'!F12/'titan_no_ap'!F12) | E34: =IF(OR('titan_ap'!H12=-1, 'titan_no_ap'!H12=-1), "", 'titan_ap'!G12/'titan_no_ap'!G12) | F34: =IF(OR('titan_ap'!H12=-1, 'titan_no_ap'!H12=-1), "", 'titan_ap'!H12/'titan_no_ap'!H12) | G34: =IF(OR('titan_ap'!H12=-1, 'titan_no_ap'!H12=-1), "", 'titan_ap'!J12/'titan_no_ap'!J12) | H34: =IF(OR('titan_ap'!H12=-1, 'titan_no_ap'!H12=-1), "", 'titan_ap'!K12/'titan_no_ap'!K12) | I34: =IF(OR('titan_ap'!H12=-1, 'titan_no_ap'!H12=-1), "", 'titan_ap'!L12/'titan_no_ap'!L12) | J34: =IF(OR('titan_ap'!H12=-1, 'titan_no_ap'!H12=-1), "", 'titan_ap'!AC12/'titan_no_ap'!AC12) | K34: =IF(OR('titan_ap'!H12=-1, 'titan_no_ap'!H12=-1), "", 'titan_ap'!AD12/'titan_no_ap'!AD12)
A35: titan | B35: stratixiv_arch.timing.xml | C35: gsm_switch_stratixiv_arch_timing.blif | D35: =IF(OR('titan_ap'!H13=-1, 'titan_no_ap'!H13=-1), "", 'titan_ap'!F13/'titan_no_ap'!F13) | E35: =IF(OR('titan_ap'!H13=-1, 'titan_no_ap'!H13=-1), "", 'titan_ap'!G13/'titan_no_ap'!G13) | F35: =IF(OR('titan_ap'!H13=-1, 'titan_no_ap'!H13=-1), "", 'titan_ap'!H13/'titan_no_ap'!H13) | G35: =IF(OR('titan_ap'!H13=-1, 'titan_no_ap'!H13=-1), "", 'titan_ap'!J13/'titan_no_ap'!J13) | H35: =IF(OR('titan_ap'!H13=-1, 'titan_no_ap'!H13=-1), "", 'titan_ap'!K13/'titan_no_ap'!K13) | I35: =IF(OR('titan_ap'!H13=-1, 'titan_no_ap'!H13=-1), "", 'titan_ap'!L13/'titan_no_ap'!L13) | J35: =IF(OR('titan_ap'!H13=-1, 'titan_no_ap'!H13=-1), "", 'titan_ap'!AC13/'titan_no_ap'!AC13) | K35: =IF(OR('titan_ap'!H13=-1, 'titan_no_ap'!H13=-1), "", 'titan_ap'!AD13/'titan_no_ap'!AD13)
... A46: titan | B46: stratixiv_arch.timing.xml | C46: gaussianblur_stratixiv_arch_timing.blif | D46: =IF(OR('titan_ap'!H24=-1, 'titan_no_ap'!H24=-1), "", 'titan_ap'!F24/'titan_no_ap'!F24) | E46: =IF(OR('titan_ap'!H24=-1, 'titan_no_ap'!H24=-1), "", 'titan_ap'!G24/'titan_no_ap'!G24) | F46: =IF(OR('titan_ap'!H24=-1, 'titan_no_ap'!H24=-1), "", 'titan_ap'!H24/'titan_no_ap'!H24) | G46: =IF(OR('titan_ap'!H24=-1, 'titan_no_ap'!H24=-1), "", 'titan_ap'!J24/'titan_no_ap'!J24) | H46: =IF(OR('titan_ap'!H24=-1, 'titan_no_ap'!H24=-1), "", 'titan_ap'!K24/'titan_no_ap'!K24) | I46: =IF(OR('titan_ap'!H24=-1, 'titan_no_ap'!H24=-1), "", 'titan_ap'!L24/'titan_no_ap'!L24) | J46: =IF(OR('titan_ap'!H24=-1, 'titan_no_ap'!H24=-1), "", 'titan_ap'!AC24/'titan_no_ap'!AC24) | K46: =IF(OR('titan_ap'!H24=-1, 'titan_no_ap'!H24=-1), "", 'titan_ap'!AD24/'titan_no_ap'!AD24)
A47: titan | C47: GEOMEAN | D47: =GEOMEAN(D24:D46) | E47: =GEOMEAN(E24:E46) | F47: =GEOMEAN(F24:F46) | G47: =GEOMEAN(G24:G46) | H47: =GEOMEAN(H24:H46) | I47: =GEOMEAN(I24:I46) | J47: =GEOMEAN(J24:J46) | K47: =GEOMEAN(K24:K46)
A48: titan | C48: UNROUTES | D48: =23 - COUNT(F24:F46)
A50: koios | B50: k6FracN10LB_mem20K_complexDSP_customSB_22nm.xml | C50: attention_layer.blif | D50: =IF(OR('koios_ap'!H2=-1, 'koios_no_ap'!H2=-1), "", 'koios_ap'!F2/'koios_no_ap'!F2) | E50: =IF(OR('koios_ap'!H2=-1, 'koios_no_ap'!H2=-1), "", 'koios_ap'!G2/'koios_no_ap'!G2) | F50: =IF(OR('koios_ap'!H2=-1, 'koios_no_ap'!H2=-1), "", 'koios_ap'!H2/'koios_no_ap'!H2) | G50: =IF(OR('koios_ap'!H2=-1, 'koios_no_ap'!H2=-1), "", 'koios_ap'!J2/'koios_no_ap'!J2) | H50: =IF(OR('koios_ap'!H2=-1, 'koios_no_ap'!H2=-1), "", 'koios_ap'!K2/'koios_no_ap'!K2) | I50: =IF(OR('koios_ap'!H2=-1, 'koios_no_ap'!H2=-1), "", 'koios_ap'!L2/'koios_no_ap'!L2) | J50: =IF(OR('koios_ap'!H2=-1, 'koios_no_ap'!H2=-1), "", 'koios_ap'!AC2/'koios_no_ap'!AC2) | K50: =IF(OR('koios_ap'!H2=-1, 'koios_no_ap'!H2=-1), "", 'koios_ap'!AD2/'koios_no_ap'!AD2)
A51: koios | B51: k6FracN10LB_mem20K_complexDSP_customSB_22nm.xml | C51: bnn.blif | D51: =IF(OR('koios_ap'!H3=-1, 'koios_no_ap'!H3=-1), "", 'koios_ap'!F3/'koios_no_ap'!F3) | E51: =IF(OR('koios_ap'!H3=-1, 'koios_no_ap'!H3=-1), "", 'koios_ap'!G3/'koios_no_ap'!G3) | F51: =IF(OR('koios_ap'!H3=-1, 'koios_no_ap'!H3=-1), "", 'koios_ap'!H3/'koios_no_ap'!H3) | G51: =IF(OR('koios_ap'!H3=-1, 'koios_no_ap'!H3=-1), "", 'koios_ap'!J3/'koios_no_ap'!J3) | H51: =IF(OR('koios_ap'!H3=-1, 'koios_no_ap'!H3=-1), "", 'koios_ap'!K3/'koios_no_ap'!K3) | I51: =IF(OR('koios_ap'!H3=-1, 'koios_no_ap'!H3=-1), "", 'koios_ap'!L3/'koios_no_ap'!L3) | J51: =IF(OR('koios_ap'!H3=-1, 'koios_no_ap'!H3=-1), "", 'koios_ap'!AC3/'koios_no_ap'!AC3) | K51: =IF(OR('koios_ap'!H3=-1, 'koios_no_ap'!H3=-1), "", 'koios_ap'!AD3/'koios_no_ap'!AD3)
A52: koios | B52: k6FracN10LB_mem20K_complexDSP_customSB_22nm.xml | C52: bwave_like.fixed.large.blif | D52: =IF(OR('koios_ap'!H4=-1, 'koios_no_ap'!H4=-1), "", 'koios_ap'!F4/'koios_no_ap'!F4) | E52: =IF(OR('koios_ap'!H4=-1, 'koios_no_ap'!H4=-1), "", 'koios_ap'!G4/'koios_no_ap'!G4) | F52: =IF(OR('koios_ap'!H4=-1, 'koios_no_ap'!H4=-1), "", 'koios_ap'!H4/'koios_no_ap'!H4) | G52: =IF(OR('koios_ap'!H4=-1, 'koios_no_ap'!H4=-1), "", 'koios_ap'!J4/'koios_no_ap'!J4) | H52: =IF(OR('koios_ap'!H4=-1, 'koios_no_ap'!H4=-1), "", 'koios_ap'!K4/'koios_no_ap'!K4) | I52: =IF(OR('koios_ap'!H4=-1, 'koios_no_ap'!H4=-1), "", 'koios_ap'!L4/'koios_no_ap'!L4) | J52: =IF(OR('koios_ap'!H4=-1, 'koios_no_ap'!H4=-1), "", 'koios_ap'!AC4/'koios_no_ap'!AC4) | K52: =IF(OR('koios_ap'!H4=-1, 'koios_no_ap'!H4=-1), "", 'koios_ap'!AD4/'koios_no_ap'!AD4)
A53: koios | B53: k6FracN10LB_mem20K_complexDSP_customSB_22nm.xml | C53: bwave_like.fixed.small.blif | D53: =IF(OR('koios_ap'!H5=-1, 'koios_no_ap'!H5=-1), "", 'koios_ap'!F5/'koios_no_ap'!F5) | E53: =IF(OR('koios_ap'!H5=-1, 'koios_no_ap'!H5=-1), "", 'koios_ap'!G5/'koios_no_ap'!G5) | F53: =IF(OR('koios_ap'!H5=-1, 'koios_no_ap'!H5=-1), "", 'koios_ap'!H5/'koios_no_ap'!H5) | G53: =IF(OR('koios_ap'!H5=-1, 'koios_no_ap'!H5=-1), "", 'koios_ap'!J5/'koios_no_ap'!J5) | H53: =IF(OR('koios_ap'!H5=-1, 'koios_no_ap'!H5=-1), "", 'koios_ap'!K5/'koios_no_ap'!K5) | I53: =IF(OR('koios_ap'!H5=-1, 'koios_no_ap'!H5=-1), "", 'koios_ap'!L5/'koios_no_ap'!L5) | J53: =IF(OR('koios_ap'!H5=-1, 'koios_no_ap'!H5=-1), "", 'koios_ap'!AC5/'koios_no_ap'!AC5) | K53: =IF(OR('koios_ap'!H5=-1, 'koios_no_ap'!H5=-1), "", 'koios_ap'!AD5/'koios_no_ap'!AD5)
...

Sheet vtr_largest_ap
A1: arch | B1: circuit | C1: script_params | D1: vpr_status | E1: post_gp_hpwl | F1: post_fl_hpwl | G1: post_dp_hpwl | H1: total_wirelength | I1: post_gp_cpd | J1: post_fl_cpd | K1: post_dp_cpd | L1: crit_path_delay | M1: post_gp_sTNS | N1: post_fl_sTNS | O1: post_dp_sTNS | P1: final_sTNS | Q1: post_gp_overfilled_bins | R1: post_gp_avg_overfill | S1: post_gp_num_misplaced_blocks | T1: post_fl_cluster_err | U1: post_fl_atom_err | V1: post_fl_total_disp | W1: post_fl_avg_disp | X1: post_fl_max_disp | Y1: ap_runtime | Z1: ap_gp_runtime | AA1: ap_fl_runtime | AB1: ap_dp_runtime | AC1: route_runtime | AD1: total_runtime | AE1: num_clb | AF1: num_lab | AG1: num_pre_packed_blocks | AH1: Unnamed: 33
A2: k6_frac_N10_frac_chain_mem32K_40nm.xml | B2: arm_core.blif | C2: common | D2: success | E2: 120581 | F2: 129620 | G2: 107787 | H2: 144282 | I2: 22.066996 | J2: 24.576 | K2: 22.3311 | L2: 23.0565 | M2: -243842.64 | N2: -255843 | O2: -221278 | P2: -227709 | Q2: 13 | R2: 25.846153 | S2: 0 | T2: 67.318665 | U2: 58.998859 | V2: 24803.629 | W2: 1.768656 | X2: 14.000199 | Y2: 33.47 | Z2: 9.9 | AA2: 14.97 | AB2: 5.49 | AC2: 2.75 | AD2: 37.95 | AE2: 891 | AF2: -1 | AG2: 14024
A3: k6_frac_N10_frac_chain_mem32K_40nm.xml | B3: bgm.blif | C3: common | D3: success | E3: 358049 | F3: 479874 | G3: 255430 | H3: 354099 | I3: 27.551311 | J3: 37.6597 | K3: 21.0056 | L3: 21.5713 | M3: -25881.725 | N3: -32415.7 | O3: -26145.8 | P3: -26574.4 | Q3: 52 | R3: 229.34616 | S3: 0 | T3: 82.534027 | U3: 71.654732 | V3: 174486.5 | W3: 5.059193 | X3: 61.934437 | Y3: 183.03 | Z3: 29.93 | AA3: 113.07 | AB3: 33.2 | AC3: 8.54 | AD3: 196.69 | AE3: 2786 | AF3: -1 | AG3: 34489
A4: k6_frac_N10_frac_chain_mem32K_40nm.xml | B4: stereovision0.blif | C4: common | D4: success | E4: 40415.8 | F4: 44229.3 | G4: 38556 | H4: 54286 | I4: 4.130682 | J4: 4.35373 | K4: 3.43744 | L4: 3.66449 | M4: -13372.565 | N4: -16280.6 | O4: -14650 | P4: -15763.4 | Q4: 33 | R4: 10.090909 | S4: 0 | T4: 58.333332 | U4: 43.358807 | V4: 21144.078 | W4: 0.99133 | X4: 13.222509 | Y4: 18.45 | Z4: 4.89 | AA4: 8.6 | AB4: 3.36 | AC4: 1.52 | AD4: 21.56 | AE4: 750 | AF4: -1 | AG4: 21329
A5: k6_frac_N10_frac_chain_mem32K_40nm.xml | B5: stereovision1.blif | C5: common | D5: success | E5: 74095.3 | F5: 95506.7 | G5: 72946 | H5: 109779 | I5: 4.919597 | J5: 5.84795 | K5: 4.99493 | L5: 5.17959 | M5: -23958.197 | N5: -26201.5 | O5: -22947.5 | P5: -24789.1 | Q5: 125 | R5: 30.247999 | S5: 0 | T5: 60.933449 | U5: 56.795059 | V5: 35955.074 | W5: 1.866439 | X5: 19.572651 | Y5: 21.17 | Z5: 5.18 | AA5: 9.11 | AB5: 4.73 | AC5: 2.59 | AD5: 25.44 | AE5: 855 | AF5: -1 | AG5: 19264
A6: k6_frac_N10_frac_chain_mem32K_40nm.xml | B6: stereovision2.blif | C6: common | D6: success | E6: 240428 | F6: 350673 | G6: 227973 | H6: 317724 | I6: 13.546613 | J6: 16.001 | K6: 12.5819 | L6: 12.8007 | M6: -37241.227 | N6: -60140.5 | O6: -47823.2 | P6: -52588.1 | Q6: 551 | R6: 32.713249 | S6: 0 | T6: 49.745762 | U6: 64.955948 | V6: 80736.562 | W6: 2.188873 | X6: 60 | Y6: 75.14 | Z6: 12.12 | AA6: 20.44 | AB6: 26.77 | AC6: 6.91 | AD6: 86.21 | AE6: 1805 | AF6: -1 | AG6: 36885
A7: k6_frac_N10_frac_chain_mem32K_40nm.xml | B7: LU8PEEng.blif | C7: common | D7: success | E7: 349366 | F7: 395143 | G7: 220336 | H7: 302346 | I7: 120.15724 | J7: 117.35 | K7: 79.3906 | L7: 78.8921 | M7: -53771.75 | N7: -58388.6 | O7: -55864.4 | P7: -67915.9 | Q7: 117 | R7: 2590.9829 | S7: 0 | T7: 79.275421 | U7: 60.558674 | V7: 101603.77 | W7: 3.203347 | X7: 48.943413 | Y7: 101.54 | Z7: 23 | AA7: 45.16 | AB7: 26.89 | AC7: 8.42 | AD7: 114.29 | AE7: 2298 | AF7: -1 | AG7: 31718
A8: k6_frac_N10_frac_chain_mem32K_40nm.xml | B8: LU32PEEng.blif | C8: common | D8: success | E8: 1233510 | F8: 1122210 | G8: 798977 | H8: 1077904 | I8: 97.073425 | J8: 77.4085 | K8: 71.449 | L8: 71.5498 | M8: -325415.88 | N8: -338272 | O8: -298780 | P8: -400360 | Q8: 321 | R8: 72.576324 | S8: 0 | T8: 86.532738 | U8: 57.636776 | V8: 304033.44 | W8: 2.830298 | X8: 66.926979 | Y8: 565.72 | Z8: 105.54 | AA8: 170.65 | AB8: 265.3 | AC8: 32.56 | AD8: 614.84 | AE8: 7648 | AF8: -1 | AG8: 107421
A9: k6_frac_N10_frac_chain_mem32K_40nm.xml | B9: mcml.blif | C9: common | D9: success | E9: 955528 | F9: 1110330 | G9: 681391 | H9: 874574 | I9: 59.717281 | J9: 63.4466 | K9: 47.3176 | L9: 46.3625 | M9: -413186.56 | N9: -358351 | O9: -323238 | P9: -387228 | Q9: 1628 | R9: 38.407864 | S9: 0 | T9: 74.344749 | U9: 76.851532 | V9: 1032531.6 | W9: 6.506472 | X9: 121.99604 | Y9: 804.9 | Z9: 80.69 | AA9: 389.1 | AB9: 306.32 | AC9: 24.66 | AD9: 846.27 | AE9: 6633 | AF9: -1 | AG9: 158693

Sheet vtr_largest_no_ap
A1: arch | B1: circuit | C1: script_params | D1: vpr_status | E1: post_gp_hpwl | F1: post_fl_hpwl | G1: post_dp_hpwl | H1: total_wirelength | I1: post_gp_cpd | J1: post_fl_cpd | K1: post_dp_cpd | L1: crit_path_delay | M1: post_gp_sTNS | N1: post_fl_sTNS | O1: post_dp_sTNS | P1: final_sTNS | Q1: post_gp_overfilled_bins | R1: post_gp_avg_overfill | S1: post_gp_num_misplaced_blocks | T1: post_fl_cluster_err | U1: post_fl_atom_err | V1: post_fl_total_disp | W1: post_fl_avg_disp | X1: post_fl_max_disp | Y1: ap_runtime | Z1: ap_gp_runtime | AA1: ap_fl_runtime | AB1: ap_dp_runtime | AC1: route_runtime | AD1: total_runtime | AE1: num_clb | AF1: num_lab | AG1: num_pre_packed_blocks | AH1: Unnamed: 33
A2: k6_frac_N10_frac_chain_mem32K_40nm.xml | B2: arm_core.blif | C2: common | D2: success | E2: -1 | F2: 294162 | G2: 115295 | H2: 158875 | I2: -1 | J2: 35.0936 | K2: 22.1867 | L2: 23.3394 | M2: -1 | N2: -356055 | O2: -206089 | P2: -213416 | Q2: -1 | R2: -1 | S2: -1 | T2: -1 | U2: -1 | V2: -1 | W2: -1 | X2: -1 | Y2: -1 | Z2: -1 | AA2: -1 | AB2: -1 | AC2: 3.01 | AD2: 44.7 | AE2: 862 | AF2: -1 | AG2: 14024
A3: k6_frac_N10_frac_chain_mem32K_40nm.xml | B3: bgm.blif | C3: common | D3: success | E3: -1 | F3: 1277140 | G3: 247963 | H3: 356202 | I3: -1 | J3: 58.417 | K3: 18.9108 | L3: 19.2414 | M3: -1 | N3: -54642 | O3: -24846.3 | P3: -25216.8 | Q3: -1 | R3: -1 | S3: -1 | T3: -1 | U3: -1 | V3: -1 | W3: -1 | X3: -1 | Y3: -1 | Z3: -1 | AA3: -1 | AB3: -1 | AC3: 9.27 | AD3: 151.68 | AE3: 2799 | AF3: -1 | AG3: 34489
A4: k6_frac_N10_frac_chain_mem32K_40nm.xml | B4: stereovision0.blif | C4: common | D4: success | E4: -1 | F4: 147118 | G4: 40132 | H4: 55478 | I4: -1 | J4: 8.92415 | K4: 3.54344 | L4: 3.81109 | M4: -1 | N4: -19262.7 | O4: -13643.9 | P4: -14903.2 | Q4: -1 | R4: -1 | S4: -1 | T4: -1 | U4: -1 | V4: -1 | W4: -1 | X4: -1 | Y4: -1 | Z4: -1 | AA4: -1 | AB4: -1 | AC4: 1.27 | AD4: 17.49 | AE4: 712 | AF4: -1 | AG4: 21329
A5: k6_frac_N10_frac_chain_mem32K_40nm.xml | B5: stereovision1.blif | C5: common | D5: success | E5: -1 | F5: 232156 | G5: 77437 | H5: 114627 | I5: -1 | J5: 7.69616 | K5: 5.20031 | L5: 5.44732 | M5: -1 | N5: -29604.5 | O5: -22727 | P5: -24855.7 | Q5: -1 | R5: -1 | S5: -1 | T5: -1 | U5: -1 | V5: -1 | W5: -1 | X5: -1 | Y5: -1 | Z5: -1 | AA5: -1 | AB5: -1 | AC5: 2.49 | AD5: 20.85 | AE5: 765 | AF5: -1 | AG5: 19264
A6: k6_frac_N10_frac_chain_mem32K_40nm.xml | B6: stereovision2.blif | C6: common | D6: success | E6: -1 | F6: 1199790 | G6: 276100 | H6: 365493 | I6: -1 | J6: 30.5236 | K6: 13.1409 | L6: 14.2003 | M6: -1 | N6: -77888.9 | O6: -50832.6 | P6: -56912.5 | Q6: -1 | R6: -1 | S6: -1 | T6: -1 | U6: -1 | V6: -1 | W6: -1 | X6: -1 | Y6: -1 | Z6: -1 | AA6: -1 | AB6: -1 | AC6: 6.38 | AD6: 83.6 | AE6: 1683 | AF6: -1 | AG6: 36885
A7: k6_frac_N10_frac_chain_mem32K_40nm.xml | B7: LU8PEEng.blif | C7: common | D7: success | E7: -1 | F7: 966191 | G7: 210256 | H7: 296437 | I7: -1 | J7: 169.949 | K7: 72.3254 | L7: 73.1333 | M7: -1 | N7: -78952.1 | O7: -55771.3 | P7: -67200.4 | Q7: -1 | R7: -1 | S7: -1 | T7: -1 | U7: -1 | V7: -1 | W7: -1 | X7: -1 | Y7: -1 | Z7: -1 | AA7: -1 | AB7: -1 | AC7: 7.8 | AD7: 112.99 | AE7: 2139 | AF7: -1 | AG7: 31718
A8: k6_frac_N10_frac_chain_mem32K_40nm.xml | B8: LU32PEEng.blif | C8: common | D8: success | E8: -1 | F8: 5950070 | G8: 929518 | H8: 1204657 | I8: -1 | J8: 169.589 | K8: 74.7944 | L8: 76.4984 | M8: -1 | N8: -448189 | O8: -316506 | P8: -458377 | Q8: -1 | R8: -1 | S8: -1 | T8: -1 | U8: -1 | V8: -1 | W8: -1 | X8: -1 | Y8: -1 | Z8: -1 | AA8: -1 | AB8: -1 | AC8: 32.24 | AD8: 679.31 | AE8: 7443 | AF8: -1 | AG8: 107421
A9: k6_frac_N10_frac_chain_mem32K_40nm.xml | B9: mcml.blif | C9: common | D9: success | E9: -1 | F9: 4741870 | G9: 709916 | H9: 902121 | I9: -1 | J9: 147.344 | K9: 50.7923 | L9: 50.9395 | M9: -1 | N9: -649123 | O9: -307046 | P9: -360165 | Q9: -1 | R9: -1 | S9: -1 | T9: -1 | U9: -1 | V9: -1 | W9: -1 | X9: -1 | Y9: -1 | Z9: -1 | AA9: -1 | AB9: -1 | AC9: 19.53 | AD9: 765.45 | AE9: 6659 | AF9: -1 | AG9: 158693

Sheet artix_7_ap
A1: arch | B1: circuit | C1: script_params | D1: vpr_status | E1: post_gp_hpwl | F1: post_fl_hpwl | G1: post_dp_hpwl | H1: total_wirelength | I1: post_gp_cpd | J1: post_fl_cpd | K1: post_dp_cpd | L1: crit_path_delay | M1: post_gp_sTNS | N1: post_fl_sTNS | O1: post_dp_sTNS | P1: final_sTNS | Q1: post_gp_overfilled_bins | R1: post_gp_avg_overfill | S1: post_gp_num_misplaced_blocks | T1: post_fl_cluster_err | U1: post_fl_atom_err | V1: post_fl_total_disp | W1: post_fl_avg_disp | X1: post_fl_max_disp | Y1: ap_runtime | Z1: ap_gp_runtime | AA1: ap_fl_runtime | AB1: ap_dp_runtime | AC1: route_runtime | AD1: total_runtime | AE1: num_clb | AF1: num_lab | AG1: num_pre_packed_blocks | AH1: Unnamed: 33
A2: 7series_BRAM_DSP_carry.xml | B2: arm_core.blif | C2: common | D2: success | E2: 140481 | F2: 154853 | G2: 127361 | H2: 158813 | I2: 21.059555 | J2: 22.1445 | K2: 19.6583 | L2: 23.7298 | M2: -202755.19 | N2: -208815 | O2: -188317 | P2: -228464 | Q2: 1 | R2: 2560 | S2: 0 | T2: 68.276321 | U2: 55.447803 | V2: 23922.439 | W2: 1.705821 | X2: 14.190552 | Y2: 544.63 | Z2: 10.39 | AA2: 39.81 | AB2: 9.42 | AC2: 10.67 | AD2: 562.15 | AE2: -1 | AF2: -1 | AG2: 14024
A3: 7series_BRAM_DSP_carry.xml | B3: bgm.blif | C3: common | D3: success | E3: 252642 | F3: 331016 | G3: 275201 | H3: 395680 | I3: 25.41894 | J3: 24.8236 | K3: 23.2605 | L3: 23.5495 | M3: -29265.643 | N3: -29193.5 | O3: -28460.9 | P3: -29880.1 | Q3: 5 | R3: 11 | S3: 0 | T3: 82.902534 | U3: 63.189068 | V3: 67070.734 | W3: 1.966653 | X3: 53.000099 | Y3: 736.29 | Z3: 29.02 | AA3: 475.54 | AB3: 69.35 | AC3: 30.52 | AD3: 773.49 | AE3: -1 | AF3: -1 | AG3: 34104
A4: 7series_BRAM_DSP_carry.xml | B4: stereovision0.blif | C4: common | D4: success | E4: 66361.5 | F4: 101581 | G4: 82651 | H4: 76870 | I4: 5.606674 | J4: 5.44261 | K4: 3.84254 | L4: 4.91417 | M4: -16651.182 | N4: -18421.8 | O4: -16310.7 | P4: -22780.3 | Q4: 30 | R4: 9.9 | S4: 0 | T4: 59.425785 | U4: 65.966522 | V4: 56996.195 | W4: 2.67224 | X4: 40.911156 | Y4: 827.3 | Z4: 5.55 | AA4: 306.93 | AB4: 12.33 | AC4: 4.27 | AD4: 838.09 | AE4: -1 | AF4: -1 | AG4: 21329
A5: 7series_BRAM_DSP_carry.xml | B5: stereovision1.blif | C5: common | D5: success | E5: 133970 | F5: 177002 | G5: 123315 | H5: 116165 | I5: 7.08984 | J5: 5.31611 | K5: 4.75964 | L5: 4.83669 | M5: -22181.455 | N5: -23447.7 | O5: -21833.3 | P5: -27672.4 | Q5: 20 | R5: 41.099998 | S5: 0 | T5: 68.950882 | U5: 76.475471 | V5: 55957.047 | W5: 2.904596 | X5: 83.000099 | Y5: 527.08 | Z5: 5.5 | AA5: 355.23 | AB5: 13.08 | AC5: 3.89 | AD5: 534.25 | AE5: -1 | AF5: -1 | AG5: 19265
A6: 7series_BRAM_DSP_carry.xml | B6: stereovision2.blif | C6: common | D6: success | E6: 393242 | F6: 639581 | G6: 341024 | H6: 314699 | I6: 16.336382 | J6: 18.5504 | K6: 13.7976 | L6: 13.9362 | M6: -41821.031 | N6: -55444.7 | O6: -43720.2 | P6: -60295.8 | Q6: 37 | R6: 51 | S6: 0 | T6: 53.006107 | U6: 88.387291 | V6: 220911.48 | W6: 5.989683 | X6: 80.272797 | Y6: 1212.1 | Z6: 13.59 | AA6: 588.97 | AB6: 111.78 | AC6: 14.59 | AD6: 1235.58 | AE6: -1 | AF6: -1 | AG6: 36882
A7: 7series_BRAM_DSP_carry.xml | B7: LU8PEEng.blif | C7: common | D7: success | E7: 291108 | F7: 370102 | G7: 276461 | H7: 336912 | I7: 151.03459 | J7: 112.535 | K7: 111.678 | L7: 94.4372 | M7: -49027.98 | N7: -51398.5 | O7: -50488.2 | P7: -75906.6 | Q7: 3 | R7: 1368.3334 | S7: 0 | T7: 77.939392 | U7: 71.780251 | V7: 103093.62 | W7: 3.21254 | X7: 31.78001 | Y7: 895.82 | Z7: 23.32 | AA7: 663.92 | AB7: 102.37 | AC7: 24.93 | AD7: 926.36 | AE7: -1 | AF7: -1 | AG7: 32091
A8: 7series_BRAM_DSP_carry.xml | B8: LU32PEEng.blif | C8: common | D8: success | E8: 1474400 | F8: 1420910 | G8: 1086927 | H8: 1283206 | I8: 135.83888 | J8: 105.954 | K8: 102.714 | L8: 90.0687 | M8: -199651.27 | N8: -265232 | O8: -246412 | P8: -495516 | Q8: 13 | R8: 556.9231 | S8: 0 | T8: 82.556961 | U8: 67.551323 | V8: 331137.19 | W8: 3.043037 | X8: 46.08712 | Y8: 3851.94 | Z8: 98.27 | AA8: 2414.34 | AB8: 819.92 | AC8: 104.1 | AD8: 3980.26 | AE8: -1 | AF8: -1 | AG8: 108818
A9: 7series_BRAM_DSP_carry.xml | B9: mcml.blif | C9: common | D9: success | E9: 1302150 | F9: 2869040 | G9: 1640899 | H9: 1085680 | I9: 87.833992 | J9: 88.9604 | K9: 67.7321 | L9: 62.5056 | M9: -446264.88 | N9: -425495 | O9: -380094 | P9: -640336 | Q9: 22 | R9: 18263.773 | S9: 0 | T9: 58.556053 | U9: 80.704514 | V9: 3083671 | W9: 18.657593 | X9: 196.18463 | Y9: 6823.18 | Z9: 74.35 | AA9: 1681.63 | AB9: 4551.64 | AC9: 71.5 | AD9: 7014.46 | AE9: -1 | AF9: -1 | AG9: 165277

Sheet artix_7_no_ap
A1: arch | B1: circuit | C1: script_params | D1: vpr_status | E1: post_gp_hpwl | F1: post_fl_hpwl | G1: post_dp_hpwl | H1: total_wirelength | I1: post_gp_cpd | J1: post_fl_cpd | K1: post_dp_cpd | L1: crit_path_delay | M1: post_gp_sTNS | N1: post_fl_sTNS | O1: post_dp_sTNS | P1: final_sTNS | Q1: post_gp_overfilled_bins | R1: post_gp_avg_overfill | S1: post_gp_num_misplaced_blocks | T1: post_fl_cluster_err | U1: post_fl_atom_err | V1: post_fl_total_disp | W1: post_fl_avg_disp | X1: post_fl_max_disp | Y1: ap_runtime | Z1: ap_gp_runtime | AA1: ap_fl_runtime | AB1: ap_dp_runtime | AC1: route_runtime | AD1: total_runtime | AE1: num_clb | AF1: num_lab | AG1: num_pre_packed_blocks | AH1: Unnamed: 33
A2: 7series_BRAM_DSP_carry.xml | B2: arm_core.blif | C2: common | D2: success | E2: -1 | F2: 648527 | G2: 144562 | H2: 182196 | I2: -1 | J2: 28.4673 | K2: 18.833 | L2: 23.5849 | M2: -1 | N2: -292224 | O2: -180382 | P2: -226097 | Q2: -1 | R2: -1 | S2: -1 | T2: -1 | U2: -1 | V2: -1 | W2: -1 | X2: -1 | Y2: -1 | Z2: -1 | AA2: -1 | AB2: -1 | AC2: 14.15 | AD2: 611.36 | AE2: -1 | AF2: -1 | AG2: 14024
A3: 7series_BRAM_DSP_carry.xml | B3: bgm.blif | C3: common | D3: success | E3: -1 | F3: 1591260 | G3: 287142 | H3: 427861 | I3: -1 | J3: 40.5903 | K3: 22.5566 | L3: 22.4924 | M3: -1 | N3: -41181.5 | O3: -27652.3 | P3: -28991.5 | Q3: -1 | R3: -1 | S3: -1 | T3: -1 | U3: -1 | V3: -1 | W3: -1 | X3: -1 | Y3: -1 | Z3: -1 | AA3: -1 | AB3: -1 | AC3: 34.83 | AD3: 1030.76 | AE3: -1 | AF3: -1 | AG3: 34104
A4: 7series_BRAM_DSP_carry.xml | B4: stereovision0.blif | C4: common | D4: success | E4: -1 | F4: 397184 | G4: 88894 | H4: 85328 | I4: -1 | J4: 8.91391 | K4: 4.20506 | L4: 4.25608 | M4: -1 | N4: -22286.9 | O4: -15677.7 | P4: -21173.4 | Q4: -1 | R4: -1 | S4: -1 | T4: -1 | U4: -1 | V4: -1 | W4: -1 | X4: -1 | Y4: -1 | Z4: -1 | AA4: -1 | AB4: -1 | AC4: 4.12 | AD4: 862.69 | AE4: -1 | AF4: -1 | AG4: 21329
A5: 7series_BRAM_DSP_carry.xml | B5: stereovision1.blif | C5: common | D5: success | E5: -1 | F5: 380516 | G5: 122334 | H5: 118551 | I5: -1 | J5: 6.17464 | K5: 5.18226 | L5: 4.85733 | M5: -1 | N5: -25922.1 | O5: -21344 | P5: -26684.2 | Q5: -1 | R5: -1 | S5: -1 | T5: -1 | U5: -1 | V5: -1 | W5: -1 | X5: -1 | Y5: -1 | Z5: -1 | AA5: -1 | AB5: -1 | AC5: 3.77 | AD5: 487.9 | AE5: -1 | AF5: -1 | AG5: 19265
A6: 7series_BRAM_DSP_carry.xml | B6: stereovision2.blif | C6: common | D6: success | E6: -1 | F6: 2247050 | G6: 472310 | H6: 446953 | I6: -1 | J6: 25.7253 | K6: 14.5368 | L6: 15.7562 | M6: -1 | N6: -68752.7 | O6: -47532 | P6: -66685.5 | Q6: -1 | R6: -1 | S6: -1 | T6: -1 | U6: -1 | V6: -1 | W6: -1 | X6: -1 | Y6: -1 | Z6: -1 | AA6: -1 | AB6: -1 | AC6: 16.57 | AD6: 1727.25 | AE6: -1 | AF6: -1 | AG6: 36882
A7: 7series_BRAM_DSP_carry.xml | B7: LU8PEEng.blif | C7: common | D7: success | E7: -1 | F7: 1238390 | G7: 294897 | H7: 361194 | I7: -1 | J7: 130.833 | K7: 108.786 | L7: 91.1028 | M7: -1 | N7: -60370 | O7: -50295.1 | P7: -75991.2 | Q7: -1 | R7: -1 | S7: -1 | T7: -1 | U7: -1 | V7: -1 | W7: -1 | X7: -1 | Y7: -1 | Z7: -1 | AA7: -1 | AB7: -1 | AC7: 26.94 | AD7: 1111.92 | AE7: -1 | AF7: -1 | AG7: 32091
A8: 7series_BRAM_DSP_carry.xml | B8: LU32PEEng.blif | C8: common | D8: success | E8: -1 | F8: 8162750 | G8: 1288359 | H8: 1503791 | I8: -1 | J8: 153.413 | K8: 102.382 | L8: 89.5124 | M8: -1 | N8: -310648 | O8: -242449 | P8: -499472 | Q8: -1 | R8: -1 | S8: -1 | T8: -1 | U8: -1 | V8: -1 | W8: -1 | X8: -1 | Y8: -1 | Z8: -1 | AA8: -1 | AB8: -1 | AC8: 128.13 | AD8: 5197.99 | AE8: -1 | AF8: -1 | AG8: 108818
A9: 7series_BRAM_DSP_carry.xml | B9: mcml.blif | C9: common | D9: success | E9: -1 | F9: 7472460 | G9: 1549733 | H9: 1043328 | I9: -1 | J9: 100.956 | K9: 69.4938 | L9: 63.6921 | M9: -1 | N9: -467613 | O9: -351945 | P9: -617344 | Q9: -1 | R9: -1 | S9: -1 | T9: -1 | U9: -1 | V9: -1 | W9: -1 | X9: -1 | Y9: -1 | Z9: -1 | AA9: -1 | AB9: -1 | AC9: 70.57 | AD9: 7505.51 | AE9: -1 | AF9: -1 | AG9: 165277

Sheet titan_ap
A1: arch | B1: circuit | C1: script_params | D1: vpr_status | E1: post_gp_hpwl | F1: post_fl_hpwl | G1: post_dp_hpwl | H1: total_wirelength | I1: post_gp_cpd | J1: post_fl_cpd | K1: post_dp_cpd | L1: crit_path_delay | M1: post_gp_sTNS | N1: post_fl_sTNS | O1: post_dp_sTNS | P1: final_sTNS | Q1: post_gp_overfilled_bins | R1: post_gp_avg_overfill | S1: post_gp_num_misplaced_blocks | T1: post_fl_cluster_err | U1: post_fl_atom_err | V1: post_fl_total_disp | W1: post_fl_avg_disp | X1: post_fl_max_disp | Y1: ap_runtime | Z1: ap_gp_runtime | AA1: ap_fl_runtime | AB1: ap_dp_runtime | AC1: route_runtime | AD1: total_runtime | AE1: num_clb | AF1: num_lab | AG1: num_pre_packed_blocks | AH1: Unnamed: 33
A2: stratixiv_arch.timing.xml | B2: LU230_stratixiv_arch_timing.blif | C2: common | D2: success | E2: 17658600 | F2: 24483000 | G2: 12784005 | H2: 13486332 | I2: 32.893135 | J2: 27.8903 | K2: 26.0492 | L2: 23.8814 | M2: -1733848.4 | N2: -3677430 | O2: -3146050 | P2: -5354900 | Q2: 2402 | R2: 141.70067 | S2: 0 | T2: 70.432251 | U2: 60.500774 | V2: 9089614 | W2: 16.002813 | X2: 333.09955 | Y2: 5022.34 | Z2: 645.73 | AA2: 736.2 | AB2: 2623.11 | AC2: 381.2 | AD2: 5562.21 | AE2: -1 | AF2: 17459 | AG2: 568001
A3: stratixiv_arch.timing.xml | B3: LU_Network_stratixiv_arch_timing.blif | C3: common | D3: success | E3: 6955520 | F3: 13253200 | G3: 4748603 | H3: 5779032 | I3: 10.494129 | J3: 24.0281 | K3: 10.2361 | L3: 11.8374 | M3: -460584.72 | N3: -1336910 | O3: -641155 | P3: -852956 | Q3: 3578 | R3: 345.47513 | S3: 0 | T3: 64.57254 | U3: 67.294258 | V3: 10740273 | W3: 17.045916 | X3: 233 | Y3: 6466.34 | Z3: 966.76 | AA3: 1900.83 | AB3: 3337.31 | AC3: 264.37 | AD3: 6911.84 | AE3: -1 | AF3: 31110 | AG3: 630079
A4: stratixiv_arch.timing.xml | B4: SLAM_spheric_stratixiv_arch_timing.blif | C4: common | D4: success | E4: 989928 | F4: 3055740 | G4: 1131725 | H4: 1471959 | I4: 104.19744 | J4: 92.2464 | K4: 83.5126 | L4: 74.0291 | M4: -328375.78 | N4: -543366 | O4: -400667 | P4: -402686 | Q4: 447 | R4: 1088.3624 | S4: 0 | T4: 64.647736 | U4: 71.204445 | V4: 1768258.1 | W4: 15.87961 | X4: 91.429306 | Y4: 897.26 | Z4: 150.88 | AA4: 378.77 | AB4: 321.02 | AC4: 102.88 | AD4: 1041.62 | AE4: -1 | AF4: 5857 | AG4: 111354
A5: stratixiv_arch.timing.xml | B5: bitcoin_miner_stratixiv_arch_timing.blif | C5: common | D5: success | E5: 11571200 | F5: 33995300 | G5: 8067151 | H5: 9509294 | I5: 11.50311 | J5: 16.589 | K5: 6.74932 | L5: 7.81849 | M5: -1486056 | N5: -1614350 | O5: -985467 | P5: -1329770 | Q5: 10778 | R5: 509.70755 | S5: 0 | T5: 63.958706 | U5: 81.402473 | V5: 29263272 | W5: 26.907841 | X5: 230 | Y5: 11538.7 | Z5: 970.55 | AA5: 4296.01 | AB5: 5990.77 | AC5: 1815.98 | AD5: 13547.85 | AE5: -1 | AF5: 30829 | AG5: 1087537
A6: stratixiv_arch.timing.xml | B6: bitonic_mesh_stratixiv_arch_timing.blif | C6: common | D6: success | E6: 4353590 | F6: 5700100 | G6: 2880433 | H6: 3908022 | I6: 11.878563 | J6: 16.4887 | K6: 11.0297 | L6: 11.4094 | M6: -944365.31 | N6: -2056860 | O6: -1652050 | P6: -1879060 | Q6: 516 | R6: 123.05426 | S6: 0 | T6: 73.734917 | U6: 64.046951 | V6: 1605511.8 | W6: 8.417014 | X6: 156.83363 | Y6: 1701.02 | Z6: 286.89 | AA6: 369.87 | AB6: 645.26 | AC6: 247.85 | AD6: 2020.42 | AE6: -1 | AF6: 7956 | AG6: 190746
A7: stratixiv_arch.timing.xml | B7: cholesky_bdti_stratixiv_arch_timing.blif | C7: common | D7: success | E7: 4015340 | F7: 2166120 | G7: 1574854 | H7: 2006223 | I7: 11.482806 | J7: 10.069 | K7: 7.53344 | L7: 8.2539 | M7: -299615.62 | N7: -721381 | O7: -624217 | P7: -820586 | Q7: 897 | R7: 2336.2642 | S7: 0 | T7: 84.458931 | U7: 55.762138 | V7: 439056.25 | W7: 1.718568 | X7: 89.943535 | Y7: 1311.55 | Z7: 250.26 | AA7: 337.52 | AB7: 497.19 | AC7: 171.13 | AD7: 1548.41 | AE7: -1 | AF7: 11058 | AG7: 255478
A8: stratixiv_arch.timing.xml | B8: cholesky_mc_stratixiv_arch_timing.blif | C8: common | D8: success | E8: 1456360 | F8: 995546 | G8: 696255 | H8: 956077 | I8: 9.224792 | J8: 8.93541 | K8: 6.81745 | L8: 7.26452 | M8: -75595.398 | N8: -319677 | O8: -231631 | P8: -315529 | Q8: 345 | R8: 2857.8928 | S8: 0 | T8: 71.030006 | U8: 58.513519 | V8: 236608.41 | W8: 2.178875 | X8: 113.0002 | Y8: 539.57 | Z8: 117.74 | AA8: 140.81 | AB8: 175.15 | AC8: 84.71 | AD8: 661.94 | AE8: -1 | AF8: 5076 | AG8: 108592
A9: stratixiv_arch.timing.xml | B9: dart_stratixiv_arch_timing.blif | C9: common | D9: success | E9: 2487380 | F9: 1690840 | G9: 1368793 | H9: 1591418 | I9: 16.825911 | J9: 19.6906 | K9: 16.3612 | L9: 17.1658 | M9: -1121900 | N9: -1877730 | O9: -1633020 | P9: -1822390 | Q9: 447 | R9: 63.27964 | S9: 0 | T9: 82.145821 | U9: 47.485931 | V9: 265483.22 | W9: 1.311669 | X9: 84.817429 | Y9: 1002.26 | Z9: 249.32 | AA9: 365.3 | AB9: 290.07 | AC9: 79.61 | AD9: 1135.59 | AE9: -1 | AF9: 7836 | AG9: 202401
A10: stratixiv_arch.timing.xml | B10: denoise_stratixiv_arch_timing.blif | C10: common | D10: success | E10: 2094240 | F10: 9988460 | G10: 2171492 | H10: 2837536 | I10: 1151.7058 | J10: 1842.68 | K10: 939.679 | L10: 842.8 | M10: -766269.56 | N10: -1845600 | O10: -982217 | P10: -1125230 | Q10: 1955 | R10: 882.74426 | S10: 0 | T10: 45.808483 | U10: 81.192635 | V10: 6957655.5 | W10: 25.320269 | X10: 199 | Y10: 2861.1 | Z10: 356.14 | AA10: 777.05 | AB10: 1612.81 | AC10: 212.62 | AD10: 3161.96 | AE10: -1 | AF10: 14006 | AG10: 274786
A11: stratixiv_arch.timing.xml | B11: des90_stratixiv_arch_timing.blif | C11: common | D11: success | E11: 2043990 | F11: 2480140 | G11: 1318427 | H11: 1911704 | I11: 11.427784 | J11: 14.6819 | K11: 11.4687 | L11: 11.5774 | M11: -547521.31 | N11: -1040150 | O11: -828875 | P11: -895583 | Q11: 565 | R11: 114.58761 | S11: 0 | T11: 74.384239 | U11: 72.69989 | V11: 726910.12 | W11: 6.575456 | X11: 97.999992 | Y11: 866.25 | Z11: 147 | AA11: 218.93 | AB11: 284.69 | AC11: 122.06 | AD11: 1030.77 | AE11: -1 | AF11: 4646 | AG11: 110549
A12: stratixiv_arch.timing.xml | B12: directrf_stratixiv_arch_timing.blif | C12: common | D12: success | E12: 20816600 | F12: 36896600 | G12: 12528911 | H12: 13340009 | I12: 11.161656 | J12: 30.4756 | K12: 12.4976 | L12: 12.4932 | M12: -409715.44 | N12: -2699930 | O12: -1887210 | P12: -2598730 | Q12: 21449 | R12: 369.74774 | S12: 0 | T12: 47.639763 | U12: 84.833328 | V12: 27188632 | W12: 29.204031 | X12: 470.40326 | Y12: 13312.77 | Z12: 785.99 | AA12: 3974 | AB12: 8115.92 | AC12: 3337.6 | AD12: 16908.93 | AE12: -1 | AF12: 58651 | AG12: 930989
A13: stratixiv_arch.timing.xml | B13: gsm_switch_stratixiv_arch_timing.blif | C13: common | D13: success | E13: 8990740 | F13: 9539800 | G13: 4285311 | H13: 5049137 | I13: 10.373495 | J13: 22.2559 | K13: 9.81451 | L13: 9.87022 | M13: -667540.44 | N13: -2055700 | O13: -1286270 | P13: -1658500 | Q13: 159 | R13: 250.03145 | S13: 0 | T13: 53.1675 | U13: 47.327309 | V13: 3931477.2 | W13: 8.022309 | X13: 259.00009 | Y13: 3667.46 | Z13: 579.81 | AA13: 611 | AB13: 2070.28 | AC13: 199.07 | AD13: 3991.34 | AE13: -1 | AF13: 34558 | AG13: 490068
... A24: stratixiv_arch.timing.xml | B24: gaussianblur_stratixiv_arch_timing.blif | C24: common | D24: success | E24: 57117000 | F24: 41091500 | G24: 31510275 | H24: 23419394 | I24: 1227.9891 | J24: 987.803 | K24: 907.841 | L24: 809.005 | M24: -63418096 | N24: -97998000 | O24: -93431800 | P24: -122818000 | Q24: 736 | R24: 73.80571 | S24: 0 | T24: 93.803436 | U24: 58.770401 | V24: 4274400.5 | W24: 2.299284 | X24: 66.459946 | Y24: 31881.62 | Z24: 2390.3 | AA24: 6266.85 | AB24: 22159.24 | AC24: 1965.72 | AD24: 34326.54 | AE24: -1 | AF24: 108198 | AG24: 1859014

Sheet titan_no_ap
A1: arch | B1: circuit | C1: script_params | D1: vpr_status | E1: post_gp_hpwl | F1: post_fl_hpwl | G1: post_dp_hpwl | H1: total_wirelength | I1: post_gp_cpd | J1: post_fl_cpd | K1: post_dp_cpd | L1: crit_path_delay | M1: post_gp_sTNS | N1: post_fl_sTNS | O1: post_dp_sTNS | P1: final_sTNS | Q1: post_gp_overfilled_bins | R1: post_gp_avg_overfill | S1: post_gp_num_misplaced_blocks | T1: post_fl_cluster_err | U1: post_fl_atom_err | V1: post_fl_total_disp | W1: post_fl_avg_disp | X1: post_fl_max_disp | Y1: ap_runtime | Z1: ap_gp_runtime | AA1: ap_fl_runtime | AB1: ap_dp_runtime | AC1: route_runtime | AD1: total_runtime | AE1: num_clb | AF1: num_lab | AG1: num_pre_packed_blocks | AH1: Unnamed: 33
A2: stratixiv_arch.timing.xml | B2: LU230_stratixiv_arch_timing.blif | C2: common | D2: success | E2: -1 | F2: 63023700 | G2: 15156882 | H2: 16050197 | I2: -1 | J2: 61.4139 | K2: 26.5017 | L2: 23.7167 | M2: -1 | N2: -4704110 | O2: -3141170 | P2: -5564920 | Q2: -1 | R2: -1 | S2: -1 | T2: -1 | U2: -1 | V2: -1 | W2: -1 | X2: -1 | Y2: -1 | Z2: -1 | AA2: -1 | AB2: -1 | AC2: 680.46 | AD2: 5936.37 | AE2: -1 | AF2: 16697 | AG2: 568001
A3: stratixiv_arch.timing.xml | B3: LU_Network_stratixiv_arch_timing.blif | C3: common | D3: success | E3: -1 | F3: 48997300 | G3: 5084526 | H3: 6138053 | I3: -1 | J3: 23.7216 | K3: 7.6282 | L3: 8.2125 | M3: -1 | N3: -3092750 | O3: -626359 | P3: -829963 | Q3: -1 | R3: -1 | S3: -1 | T3: -1 | U3: -1 | V3: -1 | W3: -1 | X3: -1 | Y3: -1 | Z3: -1 | AA3: -1 | AB3: -1 | AC3: 270.99 | AD3: 5422.11 | AE3: -1 | AF3: 31242 | AG3: 630079
A4: stratixiv_arch.timing.xml | B4: SLAM_spheric_stratixiv_arch_timing.blif | C4: common | D4: success | E4: -1 | F4: 5647430 | G4: 1165256 | H4: 1525889 | I4: -1 | J4: 136.099 | K4: 88.0519 | L4: 78.0949 | M4: -1 | N4: -729665 | O4: -405561 | P4: -414945 | Q4: -1 | R4: -1 | S4: -1 | T4: -1 | U4: -1 | V4: -1 | W4: -1 | X4: -1 | Y4: -1 | Z4: -1 | AA4: -1 | AB4: -1 | AC4: 92.03 | AD4: 742.2 | AE4: -1 | AF4: 5345 | AG4: 111354
A5: stratixiv_arch.timing.xml | B5: bitcoin_miner_stratixiv_arch_timing.blif | C5: common | D5: exited with return code -15 | E5: -1 | F5: 104376000 | G5: 10637537 | H5: -1 | I5: -1 | J5: 26.564 | K5: 8.4466 | L5: -1 | M5: -1 | N5: -2694270 | O5: -951012 | P5: -1 | Q5: -1 | R5: -1 | S5: -1 | T5: -1 | U5: -1 | V5: -1 | W5: -1 | X5: -1 | Y5: -1 | Z5: -1 | AA5: -1 | AB5: -1 | AC5: -1 | AD5: -1 | AE5: -1 | AF5: 29836 | AG5: 1087537
A6: stratixiv_arch.timing.xml | B6: bitonic_mesh_stratixiv_arch_timing.blif | C6: common | D6: success | E6: -1 | F6: 20501200 | G6: 3436369 | H6: 4495956 | I6: -1 | J6: 57.4082 | K6: 14.1523 | L6: 14.7107 | M6: -1 | N6: -4112280 | O6: -1665010 | P6: -1893050 | Q6: -1 | R6: -1 | S6: -1 | T6: -1 | U6: -1 | V6: -1 | W6: -1 | X6: -1 | Y6: -1 | Z6: -1 | AA6: -1 | AB6: -1 | AC6: 221.43 | AD6: 2021.47 | AE6: -1 | AF6: 7303 | AG6: 190746
A7: stratixiv_arch.timing.xml | B7: cholesky_bdti_stratixiv_arch_timing.blif | C7: common | D7: success | E7: -1 | F7: 12618800 | G7: 2163733 | H7: 2774242 | I7: -1 | J7: 27.0574 | K7: 9.50145 | L7: 10.2087 | M7: -1 | N7: -1136050 | O7: -528678 | P7: -764112 | Q7: -1 | R7: -1 | S7: -1 | T7: -1 | U7: -1 | V7: -1 | W7: -1 | X7: -1 | Y7: -1 | Z7: -1 | AA7: -1 | AB7: -1 | AC7: 226.55 | AD7: 1521.77 | AE7: -1 | AF7: 9665 | AG7: 255478
A8: stratixiv_arch.timing.xml | B8: cholesky_mc_stratixiv_arch_timing.blif | C8: common | D8: success | E8: -1 | F8: 3679590 | G8: 825673 | H8: 1132040 | I8: -1 | J8: 13.1792 | K8: 7.24719 | L8: 7.69557 | M8: -1 | N8: -351110 | O8: -202951 | P8: -300626 | Q8: -1 | R8: -1 | S8: -1 | T8: -1 | U8: -1 | V8: -1 | W8: -1 | X8: -1 | Y8: -1 | Z8: -1 | AA8: -1 | AB8: -1 | AC8: 61.52 | AD8: 536.69 | AE8: -1 | AF8: 4733 | AG8: 108592
A9: stratixiv_arch.timing.xml | B9: dart_stratixiv_arch_timing.blif | C9: common | D9: success | E9: -1 | F9: 10315900 | G9: 1739196 | H9: 2064807 | I9: -1 | J9: 37.2867 | K9: 13.7966 | L9: 14.3494 | M9: -1 | N9: -3434860 | O9: -1589490 | P9: -1774050 | Q9: -1 | R9: -1 | S9: -1 | T9: -1 | U9: -1 | V9: -1 | W9: -1 | X9: -1 | Y9: -1 | Z9: -1 | AA9: -1 | AB9: -1 | AC9: 94.63 | AD9: 1171.87 | AE9: -1 | AF9: 6942 | AG9: 202401
A10: stratixiv_arch.timing.xml | B10: denoise_stratixiv_arch_timing.blif | C10: common | D10: success | E10: -1 | F10: 23173800 | G10: 2380295 | H10: 3020717 | I10: -1 | J10: 2151 | K10: 972.046 | L10: 885.07 | M10: -1 | N10: -2077650 | O10: -913581 | P10: -1023990 | Q10: -1 | R10: -1 | S10: -1 | T10: -1 | U10: -1 | V10: -1 | W10: -1 | X10: -1 | Y10: -1 | Z10: -1 | AA10: -1 | AB10: -1 | AC10: 183.77 | AD10: 3201.54 | AE10: -1 | AF10: 13983 | AG10: 274786
