Workbook

Sheet summary
A1: =IF(OR(ISBLANK(summary_data!A1),ISERROR(summary_data!A1)),"",summary_data!A1) | B1: =IF(OR(ISBLANK(summary_data!A2),ISERROR(summary_data!A2)),"",summary_data!A2) | C1: =IF(OR(ISBLANK(summary_data!A3),ISERROR(summary_data!A3)),"",summary_data!A3)
A2: =IF(OR(ISBLANK(summary_data!B1),ISERROR(summary_data!B1)),"",summary_data!B1) | B2: =IF(OR(ISBLANK(summary_data!B2),ISERROR(summary_data!B2)),"",summary_data!B2) | C2: =IF(OR(ISBLANK(summary_data!B3),ISERROR(summary_data!B3)),"",summary_data!B3)
A3: =IF(OR(ISBLANK(summary_data!C1),ISERROR(summary_data!C1)),"",summary_data!C1) | B3: =IF(OR(ISBLANK(summary_data!C2),ISERROR(summary_data!C2)),"",summary_data!C2) | C3: =IF(OR(ISBLANK(summary_data!C3),ISERROR(summary_data!C3)),"",summary_data!C3)
A4: =IF(OR(ISBLANK(summary_data!D1),ISERROR(summary_data!D1)),"",summary_data!D1) | B4: =IF(OR(ISBLANK(summary_data!D2),ISERROR(summary_data!D2)),"",summary_data!D2) | C4: =IF(OR(ISBLANK(summary_data!D3),ISERROR(summary_data!D3)),"",summary_data!D3)
A5: =IF(OR(ISBLANK(summary_data!E1),ISERROR(summary_data!E1)),"",summary_data!E1) | B5: =IF(OR(ISBLANK(summary_data!E2),ISERROR(summary_data!E2)),"",summary_data!E2) | C5: =IF(OR(ISBLANK(summary_data!E3),ISERROR(summary_data!E3)),"",summary_data!E3)
A6: =IF(OR(ISBLANK(summary_data!F1),ISERROR(summary_data!F1)),"",summary_data!F1) | B6: =IF(OR(ISBLANK(summary_data!F2),ISERROR(summary_data!F2)),"",summary_data!F2) | C6: =IF(OR(ISBLANK(summary_data!F3),ISERROR(summary_data!F3)),"",summary_data!F3)
A7: =IF(OR(ISBLANK(summary_data!G1),ISERROR(summary_data!G1)),"",summary_data!G1) | B7: =IF(OR(ISBLANK(summary_data!G2),ISERROR(summary_data!G2)),"",summary_data!G2) | C7: =IF(OR(ISBLANK(summary_data!G3),ISERROR(summary_data!G3)),"",summary_data!G3)
A8: =IF(OR(ISBLANK(summary_data!H1),ISERROR(summary_data!H1)),"",summary_data!H1) | B8: =IF(OR(ISBLANK(summary_data!H2),ISERROR(summary_data!H2)),"",summary_data!H2) | C8: =IF(OR(ISBLANK(summary_data!H3),ISERROR(summary_data!H3)),"",summary_data!H3)
A9: =IF(OR(ISBLANK(summary_data!I1),ISERROR(summary_data!I1)),"",summary_data!I1) | B9: =IF(OR(ISBLANK(summary_data!I2),ISERROR(summary_data!I2)),"",summary_data!I2) | C9: =IF(OR(ISBLANK(summary_data!I3),ISERROR(summary_data!I3)),"",summary_data!I3)
A10: =IF(OR(ISBLANK(summary_data!J1),ISERROR(summary_data!J1)),"",summary_data!J1) | B10: =IF(OR(ISBLANK(summary_data!J2),ISERROR(summary_data!J2)),"",summary_data!J2) | C10: =IF(OR(ISBLANK(summary_data!J3),ISERROR(summary_data!J3)),"",summary_data!J3)
A11: =IF(OR(ISBLANK(summary_data!K1),ISERROR(summary_data!K1)),"",summary_data!K1) | B11: =IF(OR(ISBLANK(summary_data!K2),ISERROR(summary_data!K2)),"",summary_data!K2) | C11: =IF(OR(ISBLANK(summary_data!K3),ISERROR(summary_data!K3)),"",summary_data!K3)
A12: =IF(OR(ISBLANK(summary_data!L1),ISERROR(summary_data!L1)),"",summary_data!L1) | B12: =IF(OR(ISBLANK(summary_data!L2),ISERROR(summary_data!L2)),"",summary_data!L2) | C12: =IF(OR(ISBLANK(summary_data!L3),ISERROR(summary_data!L3)),"",summary_data!L3)
A13: =IF(OR(ISBLANK(summary_data!M1),ISERROR(summary_data!M1)),"",summary_data!M1) | B13: =IF(OR(ISBLANK(summary_data!M2),ISERROR(summary_data!M2)),"",summary_data!M2) | C13: =IF(OR(ISBLANK(summary_data!M3),ISERROR(summary_data!M3)),"",summary_data!M3)
A14: =IF(OR(ISBLANK(summary_data!N1),ISERROR(summary_data!N1)),"",summary_data!N1) | B14: =IF(OR(ISBLANK(summary_data!N2),ISERROR(summary_data!N2)),"",summary_data!N2) | C14: =IF(OR(ISBLANK(summary_data!N3),ISERROR(summary_data!N3)),"",summary_data!N3)
A15: =IF(OR(ISBLANK(summary_data!O1),ISERROR(summary_data!O1)),"",summary_data!O1) | B15: =IF(OR(ISBLANK(summary_data!O2),ISERROR(summary_data!O2)),"",summary_data!O2) | C15: =IF(OR(ISBLANK(summary_data!O3),ISERROR(summary_data!O3)),"",summary_data!O3)
A16: =IF(OR(ISBLANK(summary_data!P1),ISERROR(summary_data!P1)),"",summary_data!P1) | B16: =IF(OR(ISBLANK(summary_data!P2),ISERROR(summary_data!P2)),"",summary_data!P2) | C16: =IF(OR(ISBLANK(summary_data!P3),ISERROR(summary_data!P3)),"",summary_data!P3)
A17: =IF(OR(ISBLANK(summary_data!Q1),ISERROR(summary_data!Q1)),"",summary_data!Q1) | B17: =IF(OR(ISBLANK(summary_data!Q2),ISERROR(summary_data!Q2)),"",summary_data!Q2) | C17: =IF(OR(ISBLANK(summary_data!Q3),ISERROR(summary_data!Q3)),"",summary_data!Q3)
A18: =IF(OR(ISBLANK(summary_data!R1),ISERROR(summary_data!R1)),"",summary_data!R1) | B18: =IF(OR(ISBLANK(summary_data!R2),ISERROR(summary_data!R2)),"",summary_data!R2) | C18: =IF(OR(ISBLANK(summary_data!R3),ISERROR(summary_data!R3)),"",summary_data!R3)
A19: =IF(OR(ISBLANK(summary_data!S1),ISERROR(summary_data!S1)),"",summary_data!S1) | B19: =IF(OR(ISBLANK(summary_data!S2),ISERROR(summary_data!S2)),"",summary_data!S2) | C19: =IF(OR(ISBLANK(summary_data!S3),ISERROR(summary_data!S3)),"",summary_data!S3)
A20: =IF(OR(ISBLANK(summary_data!T1),ISERROR(summary_data!T1)),"",summary_data!T1) | B20: =IF(OR(ISBLANK(summary_data!T2),ISERROR(summary_data!T2)),"",summary_data!T2) | C20: =IF(OR(ISBLANK(summary_data!T3),ISERROR(summary_data!T3)),"",summary_data!T3)
A21: =IF(OR(ISBLANK(summary_data!U1),ISERROR(summary_data!U1)),"",summary_data!U1) | B21: =IF(OR(ISBLANK(summary_data!U2),ISERROR(summary_data!U2)),"",summary_data!U2) | C21: =IF(OR(ISBLANK(summary_data!U3),ISERROR(summary_data!U3)),"",summary_data!U3)

Sheet summary_data
B1: =ratios!C2 | C1: =ratios!D2 | D1: =ratios!E2 | E1: =ratios!F2 | F1: =ratios!G2 | G1: =ratios!H2 | H1: =ratios!I2 | I1: =ratios!J2 | ... U1: =ratios!V2
A2: baseline.txt | B2: =ratios!C22 | C2: =ratios!D22 | D2: =ratios!E22 | E2: =ratios!F22 | F2: =ratios!G22 | G2: =ratios!H22 | H2: =ratios!I22 | I2: =ratios!J22 | ... U2: =ratios!V22
A3: inter_pl_update.txt | B3: =ratios!C45 | C3: =ratios!D45 | D3: =ratios!E45 | E3: =ratios!F45 | F3: =ratios!G45 | G3: =ratios!H45 | H3: =ratios!I45 | I3: =ratios!J45 | ... U3: =ratios!V45

Sheet ratios
A1: baseline.txt
A2: =baseline.txt!A1 | B2: =baseline.txt!B1 | C2: =baseline.txt!D1 | D2: =baseline.txt!H1 | E2: =baseline.txt!J1 | F2: =baseline.txt!L1 | G2: =baseline.txt!M1 | H2: =baseline.txt!S1 | I2: =baseline.txt!U1 | J2: =baseline.txt!V1 | K2: =baseline.txt!AD1 | L2: =baseline.txt!AH1 | M2: =baseline.txt!AK1 | N2: =baseline.txt!AN1 | O2: =baseline.txt!AR1 | P2: =baseline.txt!AT1 | Q2: =baseline.txt!AZ1 | R2: =baseline.txt!BC1 | S2: =baseline.txt!BP1 | T2: =baseline.txt!CF1 | U2: =baseline.txt!CG1 | V2: =baseline.txt!CP1
A3: =baseline.txt!A2 | B3: =baseline.txt!B2 | C3: =IF(OR(baseline.txt!D2 = 0,baseline.txt!D2=-1),"",baseline.txt!D2 / baseline.txt!D2) | D3: =IF(OR(baseline.txt!H2 = 0,baseline.txt!H2=-1),"",baseline.txt!H2 / baseline.txt!H2) | E3: =IF(OR(baseline.txt!J2 = 0,baseline.txt!J2=-1),"",baseline.txt!J2 / baseline.txt!J2) | F3: =IF(OR(baseline.txt!L2 = 0,baseline.txt!L2=-1),"",baseline.txt!L2 / baseline.txt!L2) | G3: =IF(OR(baseline.txt!M2 = 0,baseline.txt!M2=-1),"",baseline.txt!M2 / baseline.txt!M2) | H3: =IF(OR(baseline.txt!S2 = 0,baseline.txt!S2=-1),"",baseline.txt!S2 / baseline.txt!S2) | I3: =IF(OR(baseline.txt!U2 = 0,baseline.txt!U2=-1),"",baseline.txt!U2 / baseline.txt!U2) | J3: =IF(OR(baseline.txt!V2 = 0,baseline.txt!V2=-1),"",baseline.txt!V2 / baseline.txt!V2) | K3: =IF(OR(baseline.txt!AD2 = 0,baseline.txt!AD2=-1),"",baseline.txt!AD2 / baseline.txt!AD2) | L3: =IF(OR(baseline.txt!AH2 = 0,baseline.txt!AH2=-1),"",baseline.txt!AH2 / baseline.txt!AH2) | M3: =IF(OR(baseline.txt!AK2 = 0,baseline.txt!AK2=-1),"",baseline.txt!AK2 / baseline.txt!AK2) | N3: =IF(OR(baseline.txt!AN2 = 0,baseline.txt!AN2=-1),"",baseline.txt!AN2 / baseline.txt!AN2) | O3: =IF(OR(baseline.txt!AR2 = 0,baseline.txt!AR2=-1),"",baseline.txt!AR2 / baseline.txt!AR2) | P3: =IF(OR(baseline.txt!AT2 = 0,baseline.txt!AT2=-1),"",baseline.txt!AT2 / baseline.txt!AT2) | Q3: =IF(OR(baseline.txt!AZ2 = 0,baseline.txt!AZ2=-1),"",baseline.txt!AZ2 / baseline.txt!AZ2) | R3: =IF(OR(baseline.txt!BC2 = 0,baseline.txt!BC2=-1),"",baseline.txt!BC2 / baseline.txt!BC2) | S3: =IF(OR(baseline.txt!BP2 = 0,baseline.txt!BP2=-1),"",baseline.txt!BP2 / baseline.txt!BP2) | T3: =IF(OR(baseline.txt!CF2 = 0,baseline.txt!CF2=-1),"",baseline.txt!CF2 / baseline.txt!CF2) | U3: =IF(OR(baseline.txt!CG2 = 0,baseline.txt!CG2=-1),"",baseline.txt!CG2 / baseline.txt!CG2) | V3: =IF(OR(baseline.txt!CP2 = 0,baseline.txt!CP2=-1),"",baseline.txt!CP2 / baseline.txt!CP2)
A4: =baseline.txt!A3 | B4: =baseline.txt!B3 | C4: =IF(OR(baseline.txt!D3 = 0,baseline.txt!D3=-1),"",baseline.txt!D3 / baseline.txt!D3) | D4: =IF(OR(baseline.txt!H3 = 0,baseline.txt!H3=-1),"",baseline.txt!H3 / baseline.txt!H3) | E4: =IF(OR(baseline.txt!J3 = 0,baseline.txt!J3=-1),"",baseline.txt!J3 / baseline.txt!J3) | F4: =IF(OR(baseline.txt!L3 = 0,baseline.txt!L3=-1),"",baseline.txt!L3 / baseline.txt!L3) | G4: =IF(OR(baseline.txt!M3 = 0,baseline.txt!M3=-1),"",baseline.txt!M3 / baseline.txt!M3) | H4: =IF(OR(baseline.txt!S3 = 0,baseline.txt!S3=-1),"",baseline.txt!S3 / baseline.txt!S3) | I4: =IF(OR(baseline.txt!U3 = 0,baseline.txt!U3=-1),"",baseline.txt!U3 / baseline.txt!U3) | J4: =IF(OR(baseline.txt!V3 = 0,baseline.txt!V3=-1),"",baseline.txt!V3 / baseline.txt!V3) | K4: =IF(OR(baseline.txt!AD3 = 0,baseline.txt!AD3=-1),"",baseline.txt!AD3 / baseline.txt!AD3) | L4: =IF(OR(baseline.txt!AH3 = 0,baseline.txt!AH3=-1),"",baseline.txt!AH3 / baseline.txt!AH3) | M4: =IF(OR(baseline.txt!AK3 = 0,baseline.txt!AK3=-1),"",baseline.txt!AK3 / baseline.txt!AK3) | N4: =IF(OR(baseline.txt!AN3 = 0,baseline.txt!AN3=-1),"",baseline.txt!AN3 / baseline.txt!AN3) | O4: =IF(OR(baseline.txt!AR3 = 0,baseline.txt!AR3=-1),"",baseline.txt!AR3 / baseline.txt!AR3) | P4: =IF(OR(baseline.txt!AT3 = 0,baseline.txt!AT3=-1),"",baseline.txt!AT3 / baseline.txt!AT3) | Q4: =IF(OR(baseline.txt!AZ3 = 0,baseline.txt!AZ3=-1),"",baseline.txt!AZ3 / baseline.txt!AZ3) | R4: =IF(OR(baseline.txt!BC3 = 0,baseline.txt!BC3=-1),"",baseline.txt!BC3 / baseline.txt!BC3) | S4: =IF(OR(baseline.txt!BP3 = 0,baseline.txt!BP3=-1),"",baseline.txt!BP3 / baseline.txt!BP3) | T4: =IF(OR(baseline.txt!CF3 = 0,baseline.txt!CF3=-1),"",baseline.txt!CF3 / baseline.txt!CF3) | U4: =IF(OR(baseline.txt!CG3 = 0,baseline.txt!CG3=-1),"",baseline.txt!CG3 / baseline.txt!CG3) | V4: =IF(OR(baseline.txt!CP3 = 0,baseline.txt!CP3=-1),"",baseline.txt!CP3 / baseline.txt!CP3)
A5: =baseline.txt!A4 | B5: =baseline.txt!B4 | C5: =IF(OR(baseline.txt!D4 = 0,baseline.txt!D4=-1),"",baseline.txt!D4 / baseline.txt!D4) | D5: =IF(OR(baseline.txt!H4 = 0,baseline.txt!H4=-1),"",baseline.txt!H4 / baseline.txt!H4) | E5: =IF(OR(baseline.txt!J4 = 0,baseline.txt!J4=-1),"",baseline.txt!J4 / baseline.txt!J4) | F5: =IF(OR(baseline.txt!L4 = 0,baseline.txt!L4=-1),"",baseline.txt!L4 / baseline.txt!L4) | G5: =IF(OR(baseline.txt!M4 = 0,baseline.txt!M4=-1),"",baseline.txt!M4 / baseline.txt!M4) | H5: =IF(OR(baseline.txt!S4 = 0,baseline.txt!S4=-1),"",baseline.txt!S4 / baseline.txt!S4) | I5: =IF(OR(baseline.txt!U4 = 0,baseline.txt!U4=-1),"",baseline.txt!U4 / baseline.txt!U4) | J5: =IF(OR(baseline.txt!V4 = 0,baseline.txt!V4=-1),"",baseline.txt!V4 / baseline.txt!V4) | K5: =IF(OR(baseline.txt!AD4 = 0,baseline.txt!AD4=-1),"",baseline.txt!AD4 / baseline.txt!AD4) | L5: =IF(OR(baseline.txt!AH4 = 0,baseline.txt!AH4=-1),"",baseline.txt!AH4 / baseline.txt!AH4) | M5: =IF(OR(baseline.txt!AK4 = 0,baseline.txt!AK4=-1),"",baseline.txt!AK4 / baseline.txt!AK4) | N5: =IF(OR(baseline.txt!AN4 = 0,baseline.txt!AN4=-1),"",baseline.txt!AN4 / baseline.txt!AN4) | O5: =IF(OR(baseline.txt!AR4 = 0,baseline.txt!AR4=-1),"",baseline.txt!AR4 / baseline.txt!AR4) | P5: =IF(OR(baseline.txt!AT4 = 0,baseline.txt!AT4=-1),"",baseline.txt!AT4 / baseline.txt!AT4) | Q5: =IF(OR(baseline.txt!AZ4 = 0,baseline.txt!AZ4=-1),"",baseline.txt!AZ4 / baseline.txt!AZ4) | R5: =IF(OR(baseline.txt!BC4 = 0,baseline.txt!BC4=-1),"",baseline.txt!BC4 / baseline.txt!BC4) | S5: =IF(OR(baseline.txt!BP4 = 0,baseline.txt!BP4=-1),"",baseline.txt!BP4 / baseline.txt!BP4) | T5: =IF(OR(baseline.txt!CF4 = 0,baseline.txt!CF4=-1),"",baseline.txt!CF4 / baseline.txt!CF4) | U5: =IF(OR(baseline.txt!CG4 = 0,baseline.txt!CG4=-1),"",baseline.txt!CG4 / baseline.txt!CG4) | V5: =IF(OR(baseline.txt!CP4 = 0,baseline.txt!CP4=-1),"",baseline.txt!CP4 / baseline.txt!CP4)
A6: =baseline.txt!A5 | B6: =baseline.txt!B5 | C6: =IF(OR(baseline.txt!D5 = 0,baseline.txt!D5=-1),"",baseline.txt!D5 / baseline.txt!D5) | D6: =IF(OR(baseline.txt!H5 = 0,baseline.txt!H5=-1),"",baseline.txt!H5 / baseline.txt!H5) | E6: =IF(OR(baseline.txt!J5 = 0,baseline.txt!J5=-1),"",baseline.txt!J5 / baseline.txt!J5) | F6: =IF(OR(baseline.txt!L5 = 0,baseline.txt!L5=-1),"",baseline.txt!L5 / baseline.txt!L5) | G6: =IF(OR(baseline.txt!M5 = 0,baseline.txt!M5=-1),"",baseline.txt!M5 / baseline.txt!M5) | H6: =IF(OR(baseline.txt!S5 = 0,baseline.txt!S5=-1),"",baseline.txt!S5 / baseline.txt!S5) | I6: =IF(OR(baseline.txt!U5 = 0,baseline.txt!U5=-1),"",baseline.txt!U5 / baseline.txt!U5) | J6: =IF(OR(baseline.txt!V5 = 0,baseline.txt!V5=-1),"",baseline.txt!V5 / baseline.txt!V5) | K6: =IF(OR(baseline.txt!AD5 = 0,baseline.txt!AD5=-1),"",baseline.txt!AD5 / baseline.txt!AD5) | L6: =IF(OR(baseline.txt!AH5 = 0,baseline.txt!AH5=-1),"",baseline.txt!AH5 / baseline.txt!AH5) | M6: =IF(OR(baseline.txt!AK5 = 0,baseline.txt!AK5=-1),"",baseline.txt!AK5 / baseline.txt!AK5) | N6: =IF(OR(baseline.txt!AN5 = 0,baseline.txt!AN5=-1),"",baseline.txt!AN5 / baseline.txt!AN5) | O6: =IF(OR(baseline.txt!AR5 = 0,baseline.txt!AR5=-1),"",baseline.txt!AR5 / baseline.txt!AR5) | P6: =IF(OR(baseline.txt!AT5 = 0,baseline.txt!AT5=-1),"",baseline.txt!AT5 / baseline.txt!AT5) | Q6: =IF(OR(baseline.txt!AZ5 = 0,baseline.txt!AZ5=-1),"",baseline.txt!AZ5 / baseline.txt!AZ5) | R6: =IF(OR(baseline.txt!BC5 = 0,baseline.txt!BC5=-1),"",baseline.txt!BC5 / baseline.txt!BC5) | S6: =IF(OR(baseline.txt!BP5 = 0,baseline.txt!BP5=-1),"",baseline.txt!BP5 / baseline.txt!BP5) | T6: =IF(OR(baseline.txt!CF5 = 0,baseline.txt!CF5=-1),"",baseline.txt!CF5 / baseline.txt!CF5) | U6: =IF(OR(baseline.txt!CG5 = 0,baseline.txt!CG5=-1),"",baseline.txt!CG5 / baseline.txt!CG5) | V6: =IF(OR(baseline.txt!CP5 = 0,baseline.txt!CP5=-1),"",baseline.txt!CP5 / baseline.txt!CP5)
A7: =baseline.txt!A6 | B7: =baseline.txt!B6 | C7: =IF(OR(baseline.txt!D6 = 0,baseline.txt!D6=-1),"",baseline.txt!D6 / baseline.txt!D6) | D7: =IF(OR(baseline.txt!H6 = 0,baseline.txt!H6=-1),"",baseline.txt!H6 / baseline.txt!H6) | E7: =IF(OR(baseline.txt!J6 = 0,baseline.txt!J6=-1),"",baseline.txt!J6 / baseline.txt!J6) | F7: =IF(OR(baseline.txt!L6 = 0,baseline.txt!L6=-1),"",baseline.txt!L6 / baseline.txt!L6) | G7: =IF(OR(baseline.txt!M6 = 0,baseline.txt!M6=-1),"",baseline.txt!M6 / baseline.txt!M6) | H7: =IF(OR(baseline.txt!S6 = 0,baseline.txt!S6=-1),"",baseline.txt!S6 / baseline.txt!S6) | I7: =IF(OR(baseline.txt!U6 = 0,baseline.txt!U6=-1),"",baseline.txt!U6 / baseline.txt!U6) | J7: =IF(OR(baseline.txt!V6 = 0,baseline.txt!V6=-1),"",baseline.txt!V6 / baseline.txt!V6) | K7: =IF(OR(baseline.txt!AD6 = 0,baseline.txt!AD6=-1),"",baseline.txt!AD6 / baseline.txt!AD6) | L7: =IF(OR(baseline.txt!AH6 = 0,baseline.txt!AH6=-1),"",baseline.txt!AH6 / baseline.txt!AH6) | M7: =IF(OR(baseline.txt!AK6 = 0,baseline.txt!AK6=-1),"",baseline.txt!AK6 / baseline.txt!AK6) | N7: =IF(OR(baseline.txt!AN6 = 0,baseline.txt!AN6=-1),"",baseline.txt!AN6 / baseline.txt!AN6) | O7: =IF(OR(baseline.txt!AR6 = 0,baseline.txt!AR6=-1),"",baseline.txt!AR6 / baseline.txt!AR6) | P7: =IF(OR(baseline.txt!AT6 = 0,baseline.txt!AT6=-1),"",baseline.txt!AT6 / baseline.txt!AT6) | Q7: =IF(OR(baseline.txt!AZ6 = 0,baseline.txt!AZ6=-1),"",baseline.txt!AZ6 / baseline.txt!AZ6) | R7: =IF(OR(baseline.txt!BC6 = 0,baseline.txt!BC6=-1),"",baseline.txt!BC6 / baseline.txt!BC6) | S7: =IF(OR(baseline.txt!BP6 = 0,baseline.txt!BP6=-1),"",baseline.txt!BP6 / baseline.txt!BP6) | T7: =IF(OR(baseline.txt!CF6 = 0,baseline.txt!CF6=-1),"",baseline.txt!CF6 / baseline.txt!CF6) | U7: =IF(OR(baseline.txt!CG6 = 0,baseline.txt!CG6=-1),"",baseline.txt!CG6 / baseline.txt!CG6) | V7: =IF(OR(baseline.txt!CP6 = 0,baseline.txt!CP6=-1),"",baseline.txt!CP6 / baseline.txt!CP6)
A8: =baseline.txt!A7 | B8: =baseline.txt!B7 | C8: =IF(OR(baseline.txt!D7 = 0,baseline.txt!D7=-1),"",baseline.txt!D7 / baseline.txt!D7) | D8: =IF(OR(baseline.txt!H7 = 0,baseline.txt!H7=-1),"",baseline.txt!H7 / baseline.txt!H7) | E8: =IF(OR(baseline.txt!J7 = 0,baseline.txt!J7=-1),"",baseline.txt!J7 / baseline.txt!J7) | F8: =IF(OR(baseline.txt!L7 = 0,baseline.txt!L7=-1),"",baseline.txt!L7 / baseline.txt!L7) | G8: =IF(OR(baseline.txt!M7 = 0,baseline.txt!M7=-1),"",baseline.txt!M7 / baseline.txt!M7) | H8: =IF(OR(baseline.txt!S7 = 0,baseline.txt!S7=-1),"",baseline.txt!S7 / baseline.txt!S7) | I8: =IF(OR(baseline.txt!U7 = 0,baseline.txt!U7=-1),"",baseline.txt!U7 / baseline.txt!U7) | J8: =IF(OR(baseline.txt!V7 = 0,baseline.txt!V7=-1),"",baseline.txt!V7 / baseline.txt!V7) | K8: =IF(OR(baseline.txt!AD7 = 0,baseline.txt!AD7=-1),"",baseline.txt!AD7 / baseline.txt!AD7) | L8: =IF(OR(baseline.txt!AH7 = 0,baseline.txt!AH7=-1),"",baseline.txt!AH7 / baseline.txt!AH7) | M8: =IF(OR(baseline.txt!AK7 = 0,baseline.txt!AK7=-1),"",baseline.txt!AK7 / baseline.txt!AK7) | N8: =IF(OR(baseline.txt!AN7 = 0,baseline.txt!AN7=-1),"",baseline.txt!AN7 / baseline.txt!AN7) | O8: =IF(OR(baseline.txt!AR7 = 0,baseline.txt!AR7=-1),"",baseline.txt!AR7 / baseline.txt!AR7) | P8: =IF(OR(baseline.txt!AT7 = 0,baseline.txt!AT7=-1),"",baseline.txt!AT7 / baseline.txt!AT7) | Q8: =IF(OR(baseline.txt!AZ7 = 0,baseline.txt!AZ7=-1),"",baseline.txt!AZ7 / baseline.txt!AZ7) | R8: =IF(OR(baseline.txt!BC7 = 0,baseline.txt!BC7=-1),"",baseline.txt!BC7 / baseline.txt!BC7) | S8: =IF(OR(baseline.txt!BP7 = 0,baseline.txt!BP7=-1),"",baseline.txt!BP7 / baseline.txt!BP7) | T8: =IF(OR(baseline.txt!CF7 = 0,baseline.txt!CF7=-1),"",baseline.txt!CF7 / baseline.txt!CF7) | U8: =IF(OR(baseline.txt!CG7 = 0,baseline.txt!CG7=-1),"",baseline.txt!CG7 / baseline.txt!CG7) | V8: =IF(OR(baseline.txt!CP7 = 0,baseline.txt!CP7=-1),"",baseline.txt!CP7 / baseline.txt!CP7)
A9: =baseline.txt!A8 | B9: =baseline.txt!B8 | C9: =IF(OR(baseline.txt!D8 = 0,baseline.txt!D8=-1),"",baseline.txt!D8 / baseline.txt!D8) | D9: =IF(OR(baseline.txt!H8 = 0,baseline.txt!H8=-1),"",baseline.txt!H8 / baseline.txt!H8) | E9: =IF(OR(baseline.txt!J8 = 0,baseline.txt!J8=-1),"",baseline.txt!J8 / baseline.txt!J8) | F9: =IF(OR(baseline.txt!L8 = 0,baseline.txt!L8=-1),"",baseline.txt!L8 / baseline.txt!L8) | G9: =IF(OR(baseline.txt!M8 = 0,baseline.txt!M8=-1),"",baseline.txt!M8 / baseline.txt!M8) | H9: =IF(OR(baseline.txt!S8 = 0,baseline.txt!S8=-1),"",baseline.txt!S8 / baseline.txt!S8) | I9: =IF(OR(baseline.txt!U8 = 0,baseline.txt!U8=-1),"",baseline.txt!U8 / baseline.txt!U8) | J9: =IF(OR(baseline.txt!V8 = 0,baseline.txt!V8=-1),"",baseline.txt!V8 / baseline.txt!V8) | K9: =IF(OR(baseline.txt!AD8 = 0,baseline.txt!AD8=-1),"",baseline.txt!AD8 / baseline.txt!AD8) | L9: =IF(OR(baseline.txt!AH8 = 0,baseline.txt!AH8=-1),"",baseline.txt!AH8 / baseline.txt!AH8) | M9: =IF(OR(baseline.txt!AK8 = 0,baseline.txt!AK8=-1),"",baseline.txt!AK8 / baseline.txt!AK8) | N9: =IF(OR(baseline.txt!AN8 = 0,baseline.txt!AN8=-1),"",baseline.txt!AN8 / baseline.txt!AN8) | O9: =IF(OR(baseline.txt!AR8 = 0,baseline.txt!AR8=-1),"",baseline.txt!AR8 / baseline.txt!AR8) | P9: =IF(OR(baseline.txt!AT8 = 0,baseline.txt!AT8=-1),"",baseline.txt!AT8 / baseline.txt!AT8) | Q9: =IF(OR(baseline.txt!AZ8 = 0,baseline.txt!AZ8=-1),"",baseline.txt!AZ8 / baseline.txt!AZ8) | R9: =IF(OR(baseline.txt!BC8 = 0,baseline.txt!BC8=-1),"",baseline.txt!BC8 / baseline.txt!BC8) | S9: =IF(OR(baseline.txt!BP8 = 0,baseline.txt!BP8=-1),"",baseline.txt!BP8 / baseline.txt!BP8) | T9: =IF(OR(baseline.txt!CF8 = 0,baseline.txt!CF8=-1),"",baseline.txt!CF8 / baseline.txt!CF8) | U9: =IF(OR(baseline.txt!CG8 = 0,baseline.txt!CG8=-1),"",baseline.txt!CG8 / baseline.txt!CG8) | V9: =IF(OR(baseline.txt!CP8 = 0,baseline.txt!CP8=-1),"",baseline.txt!CP8 / baseline.txt!CP8)
A10: =baseline.txt!A9 | B10: =baseline.txt!B9 | C10: =IF(OR(baseline.txt!D9 = 0,baseline.txt!D9=-1),"",baseline.txt!D9 / baseline.txt!D9) | D10: =IF(OR(baseline.txt!H9 = 0,baseline.txt!H9=-1),"",baseline.txt!H9 / baseline.txt!H9) | E10: =IF(OR(baseline.txt!J9 = 0,baseline.txt!J9=-1),"",baseline.txt!J9 / baseline.txt!J9) | F10: =IF(OR(baseline.txt!L9 = 0,baseline.txt!L9=-1),"",baseline.txt!L9 / baseline.txt!L9) | G10: =IF(OR(baseline.txt!M9 = 0,baseline.txt!M9=-1),"",baseline.txt!M9 / baseline.txt!M9) | H10: =IF(OR(baseline.txt!S9 = 0,baseline.txt!S9=-1),"",baseline.txt!S9 / baseline.txt!S9) | I10: =IF(OR(baseline.txt!U9 = 0,baseline.txt!U9=-1),"",baseline.txt!U9 / baseline.txt!U9) | J10: =IF(OR(baseline.txt!V9 = 0,baseline.txt!V9=-1),"",baseline.txt!V9 / baseline.txt!V9) | K10: =IF(OR(baseline.txt!AD9 = 0,baseline.txt!AD9=-1),"",baseline.txt!AD9 / baseline.txt!AD9) | L10: =IF(OR(baseline.txt!AH9 = 0,baseline.txt!AH9=-1),"",baseline.txt!AH9 / baseline.txt!AH9) | M10: =IF(OR(baseline.txt!AK9 = 0,baseline.txt!AK9=-1),"",baseline.txt!AK9 / baseline.txt!AK9) | N10: =IF(OR(baseline.txt!AN9 = 0,baseline.txt!AN9=-1),"",baseline.txt!AN9 / baseline.txt!AN9) | O10: =IF(OR(baseline.txt!AR9 = 0,baseline.txt!AR9=-1),"",baseline.txt!AR9 / baseline.txt!AR9) | P10: =IF(OR(baseline.txt!AT9 = 0,baseline.txt!AT9=-1),"",baseline.txt!AT9 / baseline.txt!AT9) | Q10: =IF(OR(baseline.txt!AZ9 = 0,baseline.txt!AZ9=-1),"",baseline.txt!AZ9 / baseline.txt!AZ9) | R10: =IF(OR(baseline.txt!BC9 = 0,baseline.txt!BC9=-1),"",baseline.txt!BC9 / baseline.txt!BC9) | S10: =IF(OR(baseline.txt!BP9 = 0,baseline.txt!BP9=-1),"",baseline.txt!BP9 / baseline.txt!BP9) | T10: =IF(OR(baseline.txt!CF9 = 0,baseline.txt!CF9=-1),"",baseline.txt!CF9 / baseline.txt!CF9) | U10: =IF(OR(baseline.txt!CG9 = 0,baseline.txt!CG9=-1),"",baseline.txt!CG9 / baseline.txt!CG9) | V10: =IF(OR(baseline.txt!CP9 = 0,baseline.txt!CP9=-1),"",baseline.txt!CP9 / baseline.txt!CP9)
A11: =baseline.txt!A10 | B11: =baseline.txt!B10 | C11: =IF(OR(baseline.txt!D10 = 0,baseline.txt!D10=-1),"",baseline.txt!D10 / baseline.txt!D10) | D11: =IF(OR(baseline.txt!H10 = 0,baseline.txt!H10=-1),"",baseline.txt!H10 / baseline.txt!H10) | E11: =IF(OR(baseline.txt!J10 = 0,baseline.txt!J10=-1),"",baseline.txt!J10 / baseline.txt!J10) | F11: =IF(OR(baseline.txt!L10 = 0,baseline.txt!L10=-1),"",baseline.txt!L10 / baseline.txt!L10) | G11: =IF(OR(baseline.txt!M10 = 0,baseline.txt!M10=-1),"",baseline.txt!M10 / baseline.txt!M10) | H11: =IF(OR(baseline.txt!S10 = 0,baseline.txt!S10=-1),"",baseline.txt!S10 / baseline.txt!S10) | I11: =IF(OR(baseline.txt!U10 = 0,baseline.txt!U10=-1),"",baseline.txt!U10 / baseline.txt!U10) | J11: =IF(OR(baseline.txt!V10 = 0,baseline.txt!V10=-1),"",baseline.txt!V10 / baseline.txt!V10) | K11: =IF(OR(baseline.txt!AD10 = 0,baseline.txt!AD10=-1),"",baseline.txt!AD10 / baseline.txt!AD10) | L11: =IF(OR(baseline.txt!AH10 = 0,baseline.txt!AH10=-1),"",baseline.txt!AH10 / baseline.txt!AH10) | M11: =IF(OR(baseline.txt!AK10 = 0,baseline.txt!AK10=-1),"",baseline.txt!AK10 / baseline.txt!AK10) | N11: =IF(OR(baseline.txt!AN10 = 0,baseline.txt!AN10=-1),"",baseline.txt!AN10 / baseline.txt!AN10) | O11: =IF(OR(baseline.txt!AR10 = 0,baseline.txt!AR10=-1),"",baseline.txt!AR10 / baseline.txt!AR10) | P11: =IF(OR(baseline.txt!AT10 = 0,baseline.txt!AT10=-1),"",baseline.txt!AT10 / baseline.txt!AT10) | Q11: =IF(OR(baseline.txt!AZ10 = 0,baseline.txt!AZ10=-1),"",baseline.txt!AZ10 / baseline.txt!AZ10) | R11: =IF(OR(baseline.txt!BC10 = 0,baseline.txt!BC10=-1),"",baseline.txt!BC10 / baseline.txt!BC10) | S11: =IF(OR(baseline.txt!BP10 = 0,baseline.txt!BP10=-1),"",baseline.txt!BP10 / baseline.txt!BP10) | T11: =IF(OR(baseline.txt!CF10 = 0,baseline.txt!CF10=-1),"",baseline.txt!CF10 / baseline.txt!CF10) | U11: =IF(OR(baseline.txt!CG10 = 0,baseline.txt!CG10=-1),"",baseline.txt!CG10 / baseline.txt!CG10) | V11: =IF(OR(baseline.txt!CP10 = 0,baseline.txt!CP10=-1),"",baseline.txt!CP10 / baseline.txt!CP10)
A12: =baseline.txt!A11 | B12: =baseline.txt!B11 | C12: =IF(OR(baseline.txt!D11 = 0,baseline.txt!D11=-1),"",baseline.txt!D11 / baseline.txt!D11) | D12: =IF(OR(baseline.txt!H11 = 0,baseline.txt!H11=-1),"",baseline.txt!H11 / baseline.txt!H11) | E12: =IF(OR(baseline.txt!J11 = 0,baseline.txt!J11=-1),"",baseline.txt!J11 / baseline.txt!J11) | F12: =IF(OR(baseline.txt!L11 = 0,baseline.txt!L11=-1),"",baseline.txt!L11 / baseline.txt!L11) | G12: =IF(OR(baseline.txt!M11 = 0,baseline.txt!M11=-1),"",baseline.txt!M11 / baseline.txt!M11) | H12: =IF(OR(baseline.txt!S11 = 0,baseline.txt!S11=-1),"",baseline.txt!S11 / baseline.txt!S11) | I12: =IF(OR(baseline.txt!U11 = 0,baseline.txt!U11=-1),"",baseline.txt!U11 / baseline.txt!U11) | J12: =IF(OR(baseline.txt!V11 = 0,baseline.txt!V11=-1),"",baseline.txt!V11 / baseline.txt!V11) | K12: =IF(OR(baseline.txt!AD11 = 0,baseline.txt!AD11=-1),"",baseline.txt!AD11 / baseline.txt!AD11) | L12: =IF(OR(baseline.txt!AH11 = 0,baseline.txt!AH11=-1),"",baseline.txt!AH11 / baseline.txt!AH11) | M12: =IF(OR(baseline.txt!AK11 = 0,baseline.txt!AK11=-1),"",baseline.txt!AK11 / baseline.txt!AK11) | N12: =IF(OR(baseline.txt!AN11 = 0,baseline.txt!AN11=-1),"",baseline.txt!AN11 / baseline.txt!AN11) | O12: =IF(OR(baseline.txt!AR11 = 0,baseline.txt!AR11=-1),"",baseline.txt!AR11 / baseline.txt!AR11) | P12: =IF(OR(baseline.txt!AT11 = 0,baseline.txt!AT11=-1),"",baseline.txt!AT11 / baseline.txt!AT11) | Q12: =IF(OR(baseline.txt!AZ11 = 0,baseline.txt!AZ11=-1),"",baseline.txt!AZ11 / baseline.txt!AZ11) | R12: =IF(OR(baseline.txt!BC11 = 0,baseline.txt!BC11=-1),"",baseline.txt!BC11 / baseline.txt!BC11) | S12: =IF(OR(baseline.txt!BP11 = 0,baseline.txt!BP11=-1),"",baseline.txt!BP11 / baseline.txt!BP11) | T12: =IF(OR(baseline.txt!CF11 = 0,baseline.txt!CF11=-1),"",baseline.txt!CF11 / baseline.txt!CF11) | U12: =IF(OR(baseline.txt!CG11 = 0,baseline.txt!CG11=-1),"",baseline.txt!CG11 / baseline.txt!CG11) | V12: =IF(OR(baseline.txt!CP11 = 0,baseline.txt!CP11=-1),"",baseline.txt!CP11 / baseline.txt!CP11)
A13: =baseline.txt!A12 | B13: =baseline.txt!B12 | C13: =IF(OR(baseline.txt!D12 = 0,baseline.txt!D12=-1),"",baseline.txt!D12 / baseline.txt!D12) | D13: =IF(OR(baseline.txt!H12 = 0,baseline.txt!H12=-1),"",baseline.txt!H12 / baseline.txt!H12) | E13: =IF(OR(baseline.txt!J12 = 0,baseline.txt!J12=-1),"",baseline.txt!J12 / baseline.txt!J12) | F13: =IF(OR(baseline.txt!L12 = 0,baseline.txt!L12=-1),"",baseline.txt!L12 / baseline.txt!L12) | G13: =IF(OR(baseline.txt!M12 = 0,baseline.txt!M12=-1),"",baseline.txt!M12 / baseline.txt!M12) | H13: =IF(OR(baseline.txt!S12 = 0,baseline.txt!S12=-1),"",baseline.txt!S12 / baseline.txt!S12) | I13: =IF(OR(baseline.txt!U12 = 0,baseline.txt!U12=-1),"",baseline.txt!U12 / baseline.txt!U12) | J13: =IF(OR(baseline.txt!V12 = 0,baseline.txt!V12=-1),"",baseline.txt!V12 / baseline.txt!V12) | K13: =IF(OR(baseline.txt!AD12 = 0,baseline.txt!AD12=-1),"",baseline.txt!AD12 / baseline.txt!AD12) | L13: =IF(OR(baseline.txt!AH12 = 0,baseline.txt!AH12=-1),"",baseline.txt!AH12 / baseline.txt!AH12) | M13: =IF(OR(baseline.txt!AK12 = 0,baseline.txt!AK12=-1),"",baseline.txt!AK12 / baseline.txt!AK12) | N13: =IF(OR(baseline.txt!AN12 = 0,baseline.txt!AN12=-1),"",baseline.txt!AN12 / baseline.txt!AN12) | O13: =IF(OR(baseline.txt!AR12 = 0,baseline.txt!AR12=-1),"",baseline.txt!AR12 / baseline.txt!AR12) | P13: =IF(OR(baseline.txt!AT12 = 0,baseline.txt!AT12=-1),"",baseline.txt!AT12 / baseline.txt!AT12) | Q13: =IF(OR(baseline.txt!AZ12 = 0,baseline.txt!AZ12=-1),"",baseline.txt!AZ12 / baseline.txt!AZ12) | R13: =IF(OR(baseline.txt!BC12 = 0,baseline.txt!BC12=-1),"",baseline.txt!BC12 / baseline.txt!BC12) | S13: =IF(OR(baseline.txt!BP12 = 0,baseline.txt!BP12=-1),"",baseline.txt!BP12 / baseline.txt!BP12) | T13: =IF(OR(baseline.txt!CF12 = 0,baseline.txt!CF12=-1),"",baseline.txt!CF12 / baseline.txt!CF12) | U13: =IF(OR(baseline.txt!CG12 = 0,baseline.txt!CG12=-1),"",baseline.txt!CG12 / baseline.txt!CG12) | V13: =IF(OR(baseline.txt!CP12 = 0,baseline.txt!CP12=-1),"",baseline.txt!CP12 / baseline.txt!CP12)
A14: =baseline.txt!A13 | B14: =baseline.txt!B13 | C14: =IF(OR(baseline.txt!D13 = 0,baseline.txt!D13=-1),"",baseline.txt!D13 / baseline.txt!D13) | D14: =IF(OR(baseline.txt!H13 = 0,baseline.txt!H13=-1),"",baseline.txt!H13 / baseline.txt!H13) | E14: =IF(OR(baseline.txt!J13 = 0,baseline.txt!J13=-1),"",baseline.txt!J13 / baseline.txt!J13) | F14: =IF(OR(baseline.txt!L13 = 0,baseline.txt!L13=-1),"",baseline.txt!L13 / baseline.txt!L13) | G14: =IF(OR(baseline.txt!M13 = 0,baseline.txt!M13=-1),"",baseline.txt!M13 / baseline.txt!M13) | H14: =IF(OR(baseline.txt!S13 = 0,baseline.txt!S13=-1),"",baseline.txt!S13 / baseline.txt!S13) | I14: =IF(OR(baseline.txt!U13 = 0,baseline.txt!U13=-1),"",baseline.txt!U13 / baseline.txt!U13) | J14: =IF(OR(baseline.txt!V13 = 0,baseline.txt!V13=-1),"",baseline.txt!V13 / baseline.txt!V13) | K14: =IF(OR(baseline.txt!AD13 = 0,baseline.txt!AD13=-1),"",baseline.txt!AD13 / baseline.txt!AD13) | L14: =IF(OR(baseline.txt!AH13 = 0,baseline.txt!AH13=-1),"",baseline.txt!AH13 / baseline.txt!AH13) | M14: =IF(OR(baseline.txt!AK13 = 0,baseline.txt!AK13=-1),"",baseline.txt!AK13 / baseline.txt!AK13) | N14: =IF(OR(baseline.txt!AN13 = 0,baseline.txt!AN13=-1),"",baseline.txt!AN13 / baseline.txt!AN13) | O14: =IF(OR(baseline.txt!AR13 = 0,baseline.txt!AR13=-1),"",baseline.txt!AR13 / baseline.txt!AR13) | P14: =IF(OR(baseline.txt!AT13 = 0,baseline.txt!AT13=-1),"",baseline.txt!AT13 / baseline.txt!AT13) | Q14: =IF(OR(baseline.txt!AZ13 = 0,baseline.txt!AZ13=-1),"",baseline.txt!AZ13 / baseline.txt!AZ13) | R14: =IF(OR(baseline.txt!BC13 = 0,baseline.txt!BC13=-1),"",baseline.txt!BC13 / baseline.txt!BC13) | S14: =IF(OR(baseline.txt!BP13 = 0,baseline.txt!BP13=-1),"",baseline.txt!BP13 / baseline.txt!BP13) | T14: =IF(OR(baseline.txt!CF13 = 0,baseline.txt!CF13=-1),"",baseline.txt!CF13 / baseline.txt!CF13) | U14: =IF(OR(baseline.txt!CG13 = 0,baseline.txt!CG13=-1),"",baseline.txt!CG13 / baseline.txt!CG13) | V14: =IF(OR(baseline.txt!CP13 = 0,baseline.txt!CP13=-1),"",baseline.txt!CP13 / baseline.txt!CP13)
... A21: =baseline.txt!A20 | B21: =baseline.txt!B20 | C21: =IF(OR(baseline.txt!D20 = 0,baseline.txt!D20=-1),"",baseline.txt!D20 / baseline.txt!D20) | D21: =IF(OR(baseline.txt!H20 = 0,baseline.txt!H20=-1),"",baseline.txt!H20 / baseline.txt!H20) | E21: =IF(OR(baseline.txt!J20 = 0,baseline.txt!J20=-1),"",baseline.txt!J20 / baseline.txt!J20) | F21: =IF(OR(baseline.txt!L20 = 0,baseline.txt!L20=-1),"",baseline.txt!L20 / baseline.txt!L20) | G21: =IF(OR(baseline.txt!M20 = 0,baseline.txt!M20=-1),"",baseline.txt!M20 / baseline.txt!M20) | H21: =IF(OR(baseline.txt!S20 = 0,baseline.txt!S20=-1),"",baseline.txt!S20 / baseline.txt!S20) | I21: =IF(OR(baseline.txt!U20 = 0,baseline.txt!U20=-1),"",baseline.txt!U20 / baseline.txt!U20) | J21: =IF(OR(baseline.txt!V20 = 0,baseline.txt!V20=-1),"",baseline.txt!V20 / baseline.txt!V20) | K21: =IF(OR(baseline.txt!AD20 = 0,baseline.txt!AD20=-1),"",baseline.txt!AD20 / baseline.txt!AD20) | L21: =IF(OR(baseline.txt!AH20 = 0,baseline.txt!AH20=-1),"",baseline.txt!AH20 / baseline.txt!AH20) | M21: =IF(OR(baseline.txt!AK20 = 0,baseline.txt!AK20=-1),"",baseline.txt!AK20 / baseline.txt!AK20) | N21: =IF(OR(baseline.txt!AN20 = 0,baseline.txt!AN20=-1),"",baseline.txt!AN20 / baseline.txt!AN20) | O21: =IF(OR(baseline.txt!AR20 = 0,baseline.txt!AR20=-1),"",baseline.txt!AR20 / baseline.txt!AR20) | P21: =IF(OR(baseline.txt!AT20 = 0,baseline.txt!AT20=-1),"",baseline.txt!AT20 / baseline.txt!AT20) | Q21: =IF(OR(baseline.txt!AZ20 = 0,baseline.txt!AZ20=-1),"",baseline.txt!AZ20 / baseline.txt!AZ20) | R21: =IF(OR(baseline.txt!BC20 = 0,baseline.txt!BC20=-1),"",baseline.txt!BC20 / baseline.txt!BC20) | S21: =IF(OR(baseline.txt!BP20 = 0,baseline.txt!BP20=-1),"",baseline.txt!BP20 / baseline.txt!BP20) | T21: =IF(OR(baseline.txt!CF20 = 0,baseline.txt!CF20=-1),"",baseline.txt!CF20 / baseline.txt!CF20) | U21: =IF(OR(baseline.txt!CG20 = 0,baseline.txt!CG20=-1),"",baseline.txt!CG20 / baseline.txt!CG20) | V21: =IF(OR(baseline.txt!CP20 = 0,baseline.txt!CP20=-1),"",baseline.txt!CP20 / baseline.txt!CP20)
B22: GEOMEAN | C22: =GEOMEAN(C3:C21) | D22: =GEOMEAN(D3:D21) | E22: =GEOMEAN(E3:E21) | F22: =GEOMEAN(F3:F21) | G22: =GEOMEAN(G3:G21) | H22: =GEOMEAN(H3:H21) | I22: =GEOMEAN(I3:I21) | J22: =GEOMEAN(J3:J21) | ... V22: =GEOMEAN(V3:V21)
A24: inter_pl_update.txt
A25: =baseline.txt!A1 | B25: =baseline.txt!B1 | C25: =baseline.txt!D1 | D25: =baseline.txt!H1 | E25: =baseline.txt!J1 | F25: =baseline.txt!L1 | G25: =baseline.txt!M1 | H25: =baseline.txt!S1 | I25: =baseline.txt!U1 | J25: =baseline.txt!V1 | K25: =baseline.txt!AD1 | L25: =baseline.txt!AH1 | M25: =baseline.txt!AK1 | N25: =baseline.txt!AN1 | O25: =baseline.txt!AR1 | P25: =baseline.txt!AT1 | Q25: =baseline.txt!AZ1 | R25: =baseline.txt!BC1 | S25: =baseline.txt!BP1 | T25: =baseline.txt!CF1 | U25: =baseline.txt!CG1 | V25: =baseline.txt!CP1
A26: =baseline.txt!A2 | B26: =baseline.txt!B2 | C26: =IF(OR(baseline.txt!D2 = 0,baseline.txt!D2=-1),"",inter_pl_update.txt!D2 / baseline.txt!D2) | D26: =IF(OR(baseline.txt!H2 = 0,baseline.txt!H2=-1),"",inter_pl_update.txt!H2 / baseline.txt!H2) | E26: =IF(OR(baseline.txt!J2 = 0,baseline.txt!J2=-1),"",inter_pl_update.txt!J2 / baseline.txt!J2) | F26: =IF(OR(baseline.txt!L2 = 0,baseline.txt!L2=-1),"",inter_pl_update.txt!L2 / baseline.txt!L2) | G26: =IF(OR(baseline.txt!M2 = 0,baseline.txt!M2=-1),"",inter_pl_update.txt!M2 / baseline.txt!M2) | H26: =IF(OR(baseline.txt!S2 = 0,baseline.txt!S2=-1),"",inter_pl_update.txt!S2 / baseline.txt!S2) | I26: =IF(OR(baseline.txt!U2 = 0,baseline.txt!U2=-1),"",inter_pl_update.txt!U2 / baseline.txt!U2) | J26: =IF(OR(baseline.txt!V2 = 0,baseline.txt!V2=-1),"",inter_pl_update.txt!V2 / baseline.txt!V2) | K26: =IF(OR(baseline.txt!AD2 = 0,baseline.txt!AD2=-1),"",inter_pl_update.txt!AD2 / baseline.txt!AD2) | L26: =IF(OR(baseline.txt!AH2 = 0,baseline.txt!AH2=-1),"",inter_pl_update.txt!AH2 / baseline.txt!AH2) | M26: =IF(OR(baseline.txt!AK2 = 0,baseline.txt!AK2=-1),"",inter_pl_update.txt!AK2 / baseline.txt!AK2) | N26: =IF(OR(baseline.txt!AN2 = 0,baseline.txt!AN2=-1),"",inter_pl_update.txt!AN2 / baseline.txt!AN2) | O26: =IF(OR(baseline.txt!AR2 = 0,baseline.txt!AR2=-1),"",inter_pl_update.txt!AR2 / baseline.txt!AR2) | P26: =IF(OR(baseline.txt!AT2 = 0,baseline.txt!AT2=-1),"",inter_pl_update.txt!AT2 / baseline.txt!AT2) | Q26: =IF(OR(baseline.txt!AZ2 = 0,baseline.txt!AZ2=-1),"",inter_pl_update.txt!AZ2 / baseline.txt!AZ2) | R26: =IF(OR(baseline.txt!BC2 = 0,baseline.txt!BC2=-1),"",inter_pl_update.txt!BC2 / baseline.txt!BC2) | S26: =IF(OR(baseline.txt!BP2 = 0,baseline.txt!BP2=-1),"",inter_pl_update.txt!BP2 / baseline.txt!BP2) | T26: =IF(OR(baseline.txt!CF2 = 0,baseline.txt!CF2=-1),"",inter_pl_update.txt!CF2 / baseline.txt!CF2) | U26: =IF(OR(baseline.txt!CG2 = 0,baseline.txt!CG2=-1),"",inter_pl_update.txt!CG2 / baseline.txt!CG2) | V26: =IF(OR(baseline.txt!CP2 = 0,baseline.txt!CP2=-1),"",inter_pl_update.txt!CP2 / baseline.txt!CP2)
A27: =baseline.txt!A3 | B27: =baseline.txt!B3 | C27: =IF(OR(baseline.txt!D3 = 0,baseline.txt!D3=-1),"",inter_pl_update.txt!D3 / baseline.txt!D3) | D27: =IF(OR(baseline.txt!H3 = 0,baseline.txt!H3=-1),"",inter_pl_update.txt!H3 / baseline.txt!H3) | E27: =IF(OR(baseline.txt!J3 = 0,baseline.txt!J3=-1),"",inter_pl_update.txt!J3 / baseline.txt!J3) | F27: =IF(OR(baseline.txt!L3 = 0,baseline.txt!L3=-1),"",inter_pl_update.txt!L3 / baseline.txt!L3) | G27: =IF(OR(baseline.txt!M3 = 0,baseline.txt!M3=-1),"",inter_pl_update.txt!M3 / baseline.txt!M3) | H27: =IF(OR(baseline.txt!S3 = 0,baseline.txt!S3=-1),"",inter_pl_update.txt!S3 / baseline.txt!S3) | I27: =IF(OR(baseline.txt!U3 = 0,baseline.txt!U3=-1),"",inter_pl_update.txt!U3 / baseline.txt!U3) | J27: =IF(OR(baseline.txt!V3 = 0,baseline.txt!V3=-1),"",inter_pl_update.txt!V3 / baseline.txt!V3) | K27: =IF(OR(baseline.txt!AD3 = 0,baseline.txt!AD3=-1),"",inter_pl_update.txt!AD3 / baseline.txt!AD3) | L27: =IF(OR(baseline.txt!AH3 = 0,baseline.txt!AH3=-1),"",inter_pl_update.txt!AH3 / baseline.txt!AH3) | M27: =IF(OR(baseline.txt!AK3 = 0,baseline.txt!AK3=-1),"",inter_pl_update.txt!AK3 / baseline.txt!AK3) | N27: =IF(OR(baseline.txt!AN3 = 0,baseline.txt!AN3=-1),"",inter_pl_update.txt!AN3 / baseline.txt!AN3) | O27: =IF(OR(baseline.txt!AR3 = 0,baseline.txt!AR3=-1),"",inter_pl_update.txt!AR3 / baseline.txt!AR3) | P27: =IF(OR(baseline.txt!AT3 = 0,baseline.txt!AT3=-1),"",inter_pl_update.txt!AT3 / baseline.txt!AT3) | Q27: =IF(OR(baseline.txt!AZ3 = 0,baseline.txt!AZ3=-1),"",inter_pl_update.txt!AZ3 / baseline.txt!AZ3) | R27: =IF(OR(baseline.txt!BC3 = 0,baseline.txt!BC3=-1),"",inter_pl_update.txt!BC3 / baseline.txt!BC3) | S27: =IF(OR(baseline.txt!BP3 = 0,baseline.txt!BP3=-1),"",inter_pl_update.txt!BP3 / baseline.txt!BP3) | T27: =IF(OR(baseline.txt!CF3 = 0,baseline.txt!CF3=-1),"",inter_pl_update.txt!CF3 / baseline.txt!CF3) | U27: =IF(OR(baseline.txt!CG3 = 0,baseline.txt!CG3=-1),"",inter_pl_update.txt!CG3 / baseline.txt!CG3) | V27: =IF(OR(baseline.txt!CP3 = 0,baseline.txt!CP3=-1),"",inter_pl_update.txt!CP3 / baseline.txt!CP3)
A28: =baseline.txt!A4 | B28: =baseline.txt!B4 | C28: =IF(OR(baseline.txt!D4 = 0,baseline.txt!D4=-1),"",inter_pl_update.txt!D4 / baseline.txt!D4) | D28: =IF(OR(baseline.txt!H4 = 0,baseline.txt!H4=-1),"",inter_pl_update.txt!H4 / baseline.txt!H4) | E28: =IF(OR(baseline.txt!J4 = 0,baseline.txt!J4=-1),"",inter_pl_update.txt!J4 / baseline.txt!J4) | F28: =IF(OR(baseline.txt!L4 = 0,baseline.txt!L4=-1),"",inter_pl_update.txt!L4 / baseline.txt!L4) | G28: =IF(OR(baseline.txt!M4 = 0,baseline.txt!M4=-1),"",inter_pl_update.txt!M4 / baseline.txt!M4) | H28: =IF(OR(baseline.txt!S4 = 0,baseline.txt!S4=-1),"",inter_pl_update.txt!S4 / baseline.txt!S4) | I28: =IF(OR(baseline.txt!U4 = 0,baseline.txt!U4=-1),"",inter_pl_update.txt!U4 / baseline.txt!U4) | J28: =IF(OR(baseline.txt!V4 = 0,baseline.txt!V4=-1),"",inter_pl_update.txt!V4 / baseline.txt!V4) | K28: =IF(OR(baseline.txt!AD4 = 0,baseline.txt!AD4=-1),"",inter_pl_update.txt!AD4 / baseline.txt!AD4) | L28: =IF(OR(baseline.txt!AH4 = 0,baseline.txt!AH4=-1),"",inter_pl_update.txt!AH4 / baseline.txt!AH4) | M28: =IF(OR(baseline.txt!AK4 = 0,baseline.txt!AK4=-1),"",inter_pl_update.txt!AK4 / baseline.txt!AK4) | N28: =IF(OR(baseline.txt!AN4 = 0,baseline.txt!AN4=-1),"",inter_pl_update.txt!AN4 / baseline.txt!AN4) | O28: =IF(OR(baseline.txt!AR4 = 0,baseline.txt!AR4=-1),"",inter_pl_update.txt!AR4 / baseline.txt!AR4) | P28: =IF(OR(baseline.txt!AT4 = 0,baseline.txt!AT4=-1),"",inter_pl_update.txt!AT4 / baseline.txt!AT4) | Q28: =IF(OR(baseline.txt!AZ4 = 0,baseline.txt!AZ4=-1),"",inter_pl_update.txt!AZ4 / baseline.txt!AZ4) | R28: =IF(OR(baseline.txt!BC4 = 0,baseline.txt!BC4=-1),"",inter_pl_update.txt!BC4 / baseline.txt!BC4) | S28: =IF(OR(baseline.txt!BP4 = 0,baseline.txt!BP4=-1),"",inter_pl_update.txt!BP4 / baseline.txt!BP4) | T28: =IF(OR(baseline.txt!CF4 = 0,baseline.txt!CF4=-1),"",inter_pl_update.txt!CF4 / baseline.txt!CF4) | U28: =IF(OR(baseline.txt!CG4 = 0,baseline.txt!CG4=-1),"",inter_pl_update.txt!CG4 / baseline.txt!CG4) | V28: =IF(OR(baseline.txt!CP4 = 0,baseline.txt!CP4=-1),"",inter_pl_update.txt!CP4 / baseline.txt!CP4)
A29: =baseline.txt!A5 | B29: =baseline.txt!B5 | C29: =IF(OR(baseline.txt!D5 = 0,baseline.txt!D5=-1),"",inter_pl_update.txt!D5 / baseline.txt!D5) | D29: =IF(OR(baseline.txt!H5 = 0,baseline.txt!H5=-1),"",inter_pl_update.txt!H5 / baseline.txt!H5) | E29: =IF(OR(baseline.txt!J5 = 0,baseline.txt!J5=-1),"",inter_pl_update.txt!J5 / baseline.txt!J5) | F29: =IF(OR(baseline.txt!L5 = 0,baseline.txt!L5=-1),"",inter_pl_update.txt!L5 / baseline.txt!L5) | G29: =IF(OR(baseline.txt!M5 = 0,baseline.txt!M5=-1),"",inter_pl_update.txt!M5 / baseline.txt!M5) | H29: =IF(OR(baseline.txt!S5 = 0,baseline.txt!S5=-1),"",inter_pl_update.txt!S5 / baseline.txt!S5) | I29: =IF(OR(baseline.txt!U5 = 0,baseline.txt!U5=-1),"",inter_pl_update.txt!U5 / baseline.txt!U5) | J29: =IF(OR(baseline.txt!V5 = 0,baseline.txt!V5=-1),"",inter_pl_update.txt!V5 / baseline.txt!V5) | K29: =IF(OR(baseline.txt!AD5 = 0,baseline.txt!AD5=-1),"",inter_pl_update.txt!AD5 / baseline.txt!AD5) | L29: =IF(OR(baseline.txt!AH5 = 0,baseline.txt!AH5=-1),"",inter_pl_update.txt!AH5 / baseline.txt!AH5) | M29: =IF(OR(baseline.txt!AK5 = 0,baseline.txt!AK5=-1),"",inter_pl_update.txt!AK5 / baseline.txt!AK5) | N29: =IF(OR(baseline.txt!AN5 = 0,baseline.txt!AN5=-1),"",inter_pl_update.txt!AN5 / baseline.txt!AN5) | O29: =IF(OR(baseline.txt!AR5 = 0,baseline.txt!AR5=-1),"",inter_pl_update.txt!AR5 / baseline.txt!AR5) | P29: =IF(OR(baseline.txt!AT5 = 0,baseline.txt!AT5=-1),"",inter_pl_update.txt!AT5 / baseline.txt!AT5) | Q29: =IF(OR(baseline.txt!AZ5 = 0,baseline.txt!AZ5=-1),"",inter_pl_update.txt!AZ5 / baseline.txt!AZ5) | R29: =IF(OR(baseline.txt!BC5 = 0,baseline.txt!BC5=-1),"",inter_pl_update.txt!BC5 / baseline.txt!BC5) | S29: =IF(OR(baseline.txt!BP5 = 0,baseline.txt!BP5=-1),"",inter_pl_update.txt!BP5 / baseline.txt!BP5) | T29: =IF(OR(baseline.txt!CF5 = 0,baseline.txt!CF5=-1),"",inter_pl_update.txt!CF5 / baseline.txt!CF5) | U29: =IF(OR(baseline.txt!CG5 = 0,baseline.txt!CG5=-1),"",inter_pl_update.txt!CG5 / baseline.txt!CG5) | V29: =IF(OR(baseline.txt!CP5 = 0,baseline.txt!CP5=-1),"",inter_pl_update.txt!CP5 / baseline.txt!CP5)
A30: =baseline.txt!A6 | B30: =baseline.txt!B6 | C30: =IF(OR(baseline.txt!D6 = 0,baseline.txt!D6=-1),"",inter_pl_update.txt!D6 / baseline.txt!D6) | D30: =IF(OR(baseline.txt!H6 = 0,baseline.txt!H6=-1),"",inter_pl_update.txt!H6 / baseline.txt!H6) | E30: =IF(OR(baseline.txt!J6 = 0,baseline.txt!J6=-1),"",inter_pl_update.txt!J6 / baseline.txt!J6) | F30: =IF(OR(baseline.txt!L6 = 0,baseline.txt!L6=-1),"",inter_pl_update.txt!L6 / baseline.txt!L6) | G30: =IF(OR(baseline.txt!M6 = 0,baseline.txt!M6=-1),"",inter_pl_update.txt!M6 / baseline.txt!M6) | H30: =IF(OR(baseline.txt!S6 = 0,baseline.txt!S6=-1),"",inter_pl_update.txt!S6 / baseline.txt!S6) | I30: =IF(OR(baseline.txt!U6 = 0,baseline.txt!U6=-1),"",inter_pl_update.txt!U6 / baseline.txt!U6) | J30: =IF(OR(baseline.txt!V6 = 0,baseline.txt!V6=-1),"",inter_pl_update.txt!V6 / baseline.txt!V6) | K30: =IF(OR(baseline.txt!AD6 = 0,baseline.txt!AD6=-1),"",inter_pl_update.txt!AD6 / baseline.txt!AD6) | L30: =IF(OR(baseline.txt!AH6 = 0,baseline.txt!AH6=-1),"",inter_pl_update.txt!AH6 / baseline.txt!AH6) | M30: =IF(OR(baseline.txt!AK6 = 0,baseline.txt!AK6=-1),"",inter_pl_update.txt!AK6 / baseline.txt!AK6) | N30: =IF(OR(baseline.txt!AN6 = 0,baseline.txt!AN6=-1),"",inter_pl_update.txt!AN6 / baseline.txt!AN6) | O30: =IF(OR(baseline.txt!AR6 = 0,baseline.txt!AR6=-1),"",inter_pl_update.txt!AR6 / baseline.txt!AR6) | P30: =IF(OR(baseline.txt!AT6 = 0,baseline.txt!AT6=-1),"",inter_pl_update.txt!AT6 / baseline.txt!AT6) | Q30: =IF(OR(baseline.txt!AZ6 = 0,baseline.txt!AZ6=-1),"",inter_pl_update.txt!AZ6 / baseline.txt!AZ6) | R30: =IF(OR(baseline.txt!BC6 = 0,baseline.txt!BC6=-1),"",inter_pl_update.txt!BC6 / baseline.txt!BC6) | S30: =IF(OR(baseline.txt!BP6 = 0,baseline.txt!BP6=-1),"",inter_pl_update.txt!BP6 / baseline.txt!BP6) | T30: =IF(OR(baseline.txt!CF6 = 0,baseline.txt!CF6=-1),"",inter_pl_update.txt!CF6 / baseline.txt!CF6) | U30: =IF(OR(baseline.txt!CG6 = 0,baseline.txt!CG6=-1),"",inter_pl_update.txt!CG6 / baseline.txt!CG6) | V30: =IF(OR(baseline.txt!CP6 = 0,baseline.txt!CP6=-1),"",inter_pl_update.txt!CP6 / baseline.txt!CP6)
A31: =baseline.txt!A7 | B31: =baseline.txt!B7 | C31: =IF(OR(baseline.txt!D7 = 0,baseline.txt!D7=-1),"",inter_pl_update.txt!D7 / baseline.txt!D7) | D31: =IF(OR(baseline.txt!H7 = 0,baseline.txt!H7=-1),"",inter_pl_update.txt!H7 / baseline.txt!H7) | E31: =IF(OR(baseline.txt!J7 = 0,baseline.txt!J7=-1),"",inter_pl_update.txt!J7 / baseline.txt!J7) | F31: =IF(OR(baseline.txt!L7 = 0,baseline.txt!L7=-1),"",inter_pl_update.txt!L7 / baseline.txt!L7) | G31: =IF(OR(baseline.txt!M7 = 0,baseline.txt!M7=-1),"",inter_pl_update.txt!M7 / baseline.txt!M7) | H31: =IF(OR(baseline.txt!S7 = 0,baseline.txt!S7=-1),"",inter_pl_update.txt!S7 / baseline.txt!S7) | I31: =IF(OR(baseline.txt!U7 = 0,baseline.txt!U7=-1),"",inter_pl_update.txt!U7 / baseline.txt!U7) | J31: =IF(OR(baseline.txt!V7 = 0,baseline.txt!V7=-1),"",inter_pl_update.txt!V7 / baseline.txt!V7) | K31: =IF(OR(baseline.txt!AD7 = 0,baseline.txt!AD7=-1),"",inter_pl_update.txt!AD7 / baseline.txt!AD7) | L31: =IF(OR(baseline.txt!AH7 = 0,baseline.txt!AH7=-1),"",inter_pl_update.txt!AH7 / baseline.txt!AH7) | M31: =IF(OR(baseline.txt!AK7 = 0,baseline.txt!AK7=-1),"",inter_pl_update.txt!AK7 / baseline.txt!AK7) | N31: =IF(OR(baseline.txt!AN7 = 0,baseline.txt!AN7=-1),"",inter_pl_update.txt!AN7 / baseline.txt!AN7) | O31: =IF(OR(baseline.txt!AR7 = 0,baseline.txt!AR7=-1),"",inter_pl_update.txt!AR7 / baseline.txt!AR7) | P31: =IF(OR(baseline.txt!AT7 = 0,baseline.txt!AT7=-1),"",inter_pl_update.txt!AT7 / baseline.txt!AT7) | Q31: =IF(OR(baseline.txt!AZ7 = 0,baseline.txt!AZ7=-1),"",inter_pl_update.txt!AZ7 / baseline.txt!AZ7) | R31: =IF(OR(baseline.txt!BC7 = 0,baseline.txt!BC7=-1),"",inter_pl_update.txt!BC7 / baseline.txt!BC7) | S31: =IF(OR(baseline.txt!BP7 = 0,baseline.txt!BP7=-1),"",inter_pl_update.txt!BP7 / baseline.txt!BP7) | T31: =IF(OR(baseline.txt!CF7 = 0,baseline.txt!CF7=-1),"",inter_pl_update.txt!CF7 / baseline.txt!CF7) | U31: =IF(OR(baseline.txt!CG7 = 0,baseline.txt!CG7=-1),"",inter_pl_update.txt!CG7 / baseline.txt!CG7) | V31: =IF(OR(baseline.txt!CP7 = 0,baseline.txt!CP7=-1),"",inter_pl_update.txt!CP7 / baseline.txt!CP7)
A32: =baseline.txt!A8 | B32: =baseline.txt!B8 | C32: =IF(OR(baseline.txt!D8 = 0,baseline.txt!D8=-1),"",inter_pl_update.txt!D8 / baseline.txt!D8) | D32: =IF(OR(baseline.txt!H8 = 0,baseline.txt!H8=-1),"",inter_pl_update.txt!H8 / baseline.txt!H8) | E32: =IF(OR(baseline.txt!J8 = 0,baseline.txt!J8=-1),"",inter_pl_update.txt!J8 / baseline.txt!J8) | F32: =IF(OR(baseline.txt!L8 = 0,baseline.txt!L8=-1),"",inter_pl_update.txt!L8 / baseline.txt!L8) | G32: =IF(OR(baseline.txt!M8 = 0,baseline.txt!M8=-1),"",inter_pl_update.txt!M8 / baseline.txt!M8) | H32: =IF(OR(baseline.txt!S8 = 0,baseline.txt!S8=-1),"",inter_pl_update.txt!S8 / baseline.txt!S8) | I32: =IF(OR(baseline.txt!U8 = 0,baseline.txt!U8=-1),"",inter_pl_update.txt!U8 / baseline.txt!U8) | J32: =IF(OR(baseline.txt!V8 = 0,baseline.txt!V8=-1),"",inter_pl_update.txt!V8 / baseline.txt!V8) | K32: =IF(OR(baseline.txt!AD8 = 0,baseline.txt!AD8=-1),"",inter_pl_update.txt!AD8 / baseline.txt!AD8) | L32: =IF(OR(baseline.txt!AH8 = 0,baseline.txt!AH8=-1),"",inter_pl_update.txt!AH8 / baseline.txt!AH8) | M32: =IF(OR(baseline.txt!AK8 = 0,baseline.txt!AK8=-1),"",inter_pl_update.txt!AK8 / baseline.txt!AK8) | N32: =IF(OR(baseline.txt!AN8 = 0,baseline.txt!AN8=-1),"",inter_pl_update.txt!AN8 / baseline.txt!AN8) | O32: =IF(OR(baseline.txt!AR8 = 0,baseline.txt!AR8=-1),"",inter_pl_update.txt!AR8 / baseline.txt!AR8) | P32: =IF(OR(baseline.txt!AT8 = 0,baseline.txt!AT8=-1),"",inter_pl_update.txt!AT8 / baseline.txt!AT8) | Q32: =IF(OR(baseline.txt!AZ8 = 0,baseline.txt!AZ8=-1),"",inter_pl_update.txt!AZ8 / baseline.txt!AZ8) | R32: =IF(OR(baseline.txt!BC8 = 0,baseline.txt!BC8=-1),"",inter_pl_update.txt!BC8 / baseline.txt!BC8) | S32: =IF(OR(baseline.txt!BP8 = 0,baseline.txt!BP8=-1),"",inter_pl_update.txt!BP8 / baseline.txt!BP8) | T32: =IF(OR(baseline.txt!CF8 = 0,baseline.txt!CF8=-1),"",inter_pl_update.txt!CF8 / baseline.txt!CF8) | U32: =IF(OR(baseline.txt!CG8 = 0,baseline.txt!CG8=-1),"",inter_pl_update.txt!CG8 / baseline.txt!CG8) | V32: =IF(OR(baseline.txt!CP8 = 0,baseline.txt!CP8=-1),"",inter_pl_update.txt!CP8 / baseline.txt!CP8)
A33: =baseline.txt!A9 | B33: =baseline.txt!B9 | C33: =IF(OR(baseline.txt!D9 = 0,baseline.txt!D9=-1),"",inter_pl_update.txt!D9 / baseline.txt!D9) | D33: =IF(OR(baseline.txt!H9 = 0,baseline.txt!H9=-1),"",inter_pl_update.txt!H9 / baseline.txt!H9) | E33: =IF(OR(baseline.txt!J9 = 0,baseline.txt!J9=-1),"",inter_pl_update.txt!J9 / baseline.txt!J9) | F33: =IF(OR(baseline.txt!L9 = 0,baseline.txt!L9=-1),"",inter_pl_update.txt!L9 / baseline.txt!L9) | G33: =IF(OR(baseline.txt!M9 = 0,baseline.txt!M9=-1),"",inter_pl_update.txt!M9 / baseline.txt!M9) | H33: =IF(OR(baseline.txt!S9 = 0,baseline.txt!S9=-1),"",inter_pl_update.txt!S9 / baseline.txt!S9) | I33: =IF(OR(baseline.txt!U9 = 0,baseline.txt!U9=-1),"",inter_pl_update.txt!U9 / baseline.txt!U9) | J33: =IF(OR(baseline.txt!V9 = 0,baseline.txt!V9=-1),"",inter_pl_update.txt!V9 / baseline.txt!V9) | K33: =IF(OR(baseline.txt!AD9 = 0,baseline.txt!AD9=-1),"",inter_pl_update.txt!AD9 / baseline.txt!AD9) | L33: =IF(OR(baseline.txt!AH9 = 0,baseline.txt!AH9=-1),"",inter_pl_update.txt!AH9 / baseline.txt!AH9) | M33: =IF(OR(baseline.txt!AK9 = 0,baseline.txt!AK9=-1),"",inter_pl_update.txt!AK9 / baseline.txt!AK9) | N33: =IF(OR(baseline.txt!AN9 = 0,baseline.txt!AN9=-1),"",inter_pl_update.txt!AN9 / baseline.txt!AN9) | O33: =IF(OR(baseline.txt!AR9 = 0,baseline.txt!AR9=-1),"",inter_pl_update.txt!AR9 / baseline.txt!AR9) | P33: =IF(OR(baseline.txt!AT9 = 0,baseline.txt!AT9=-1),"",inter_pl_update.txt!AT9 / baseline.txt!AT9) | Q33: =IF(OR(baseline.txt!AZ9 = 0,baseline.txt!AZ9=-1),"",inter_pl_update.txt!AZ9 / baseline.txt!AZ9) | R33: =IF(OR(baseline.txt!BC9 = 0,baseline.txt!BC9=-1),"",inter_pl_update.txt!BC9 / baseline.txt!BC9) | S33: =IF(OR(baseline.txt!BP9 = 0,baseline.txt!BP9=-1),"",inter_pl_update.txt!BP9 / baseline.txt!BP9) | T33: =IF(OR(baseline.txt!CF9 = 0,baseline.txt!CF9=-1),"",inter_pl_update.txt!CF9 / baseline.txt!CF9) | U33: =IF(OR(baseline.txt!CG9 = 0,baseline.txt!CG9=-1),"",inter_pl_update.txt!CG9 / baseline.txt!CG9) | V33: =IF(OR(baseline.txt!CP9 = 0,baseline.txt!CP9=-1),"",inter_pl_update.txt!CP9 / baseline.txt!CP9)
A34: =baseline.txt!A10 | B34: =baseline.txt!B10 | C34: =IF(OR(baseline.txt!D10 = 0,baseline.txt!D10=-1),"",inter_pl_update.txt!D10 / baseline.txt!D10) | D34: =IF(OR(baseline.txt!H10 = 0,baseline.txt!H10=-1),"",inter_pl_update.txt!H10 / baseline.txt!H10) | E34: =IF(OR(baseline.txt!J10 = 0,baseline.txt!J10=-1),"",inter_pl_update.txt!J10 / baseline.txt!J10) | F34: =IF(OR(baseline.txt!L10 = 0,baseline.txt!L10=-1),"",inter_pl_update.txt!L10 / baseline.txt!L10) | G34: =IF(OR(baseline.txt!M10 = 0,baseline.txt!M10=-1),"",inter_pl_update.txt!M10 / baseline.txt!M10) | H34: =IF(OR(baseline.txt!S10 = 0,baseline.txt!S10=-1),"",inter_pl_update.txt!S10 / baseline.txt!S10) | I34: =IF(OR(baseline.txt!U10 = 0,baseline.txt!U10=-1),"",inter_pl_update.txt!U10 / baseline.txt!U10) | J34: =IF(OR(baseline.txt!V10 = 0,baseline.txt!V10=-1),"",inter_pl_update.txt!V10 / baseline.txt!V10) | K34: =IF(OR(baseline.txt!AD10 = 0,baseline.txt!AD10=-1),"",inter_pl_update.txt!AD10 / baseline.txt!AD10) | L34: =IF(OR(baseline.txt!AH10 = 0,baseline.txt!AH10=-1),"",inter_pl_update.txt!AH10 / baseline.txt!AH10) | M34: =IF(OR(baseline.txt!AK10 = 0,baseline.txt!AK10=-1),"",inter_pl_update.txt!AK10 / baseline.txt!AK10) | N34: =IF(OR(baseline.txt!AN10 = 0,baseline.txt!AN10=-1),"",inter_pl_update.txt!AN10 / baseline.txt!AN10) | O34: =IF(OR(baseline.txt!AR10 = 0,baseline.txt!AR10=-1),"",inter_pl_update.txt!AR10 / baseline.txt!AR10) | P34: =IF(OR(baseline.txt!AT10 = 0,baseline.txt!AT10=-1),"",inter_pl_update.txt!AT10 / baseline.txt!AT10) | Q34: =IF(OR(baseline.txt!AZ10 = 0,baseline.txt!AZ10=-1),"",inter_pl_update.txt!AZ10 / baseline.txt!AZ10) | R34: =IF(OR(baseline.txt!BC10 = 0,baseline.txt!BC10=-1),"",inter_pl_update.txt!BC10 / baseline.txt!BC10) | S34: =IF(OR(baseline.txt!BP10 = 0,baseline.txt!BP10=-1),"",inter_pl_update.txt!BP10 / baseline.txt!BP10) | T34: =IF(OR(baseline.txt!CF10 = 0,baseline.txt!CF10=-1),"",inter_pl_update.txt!CF10 / baseline.txt!CF10) | U34: =IF(OR(baseline.txt!CG10 = 0,baseline.txt!CG10=-1),"",inter_pl_update.txt!CG10 / baseline.txt!CG10) | V34: =IF(OR(baseline.txt!CP10 = 0,baseline.txt!CP10=-1),"",inter_pl_update.txt!CP10 / baseline.txt!CP10)
A35: =baseline.txt!A11 | B35: =baseline.txt!B11 | C35: =IF(OR(baseline.txt!D11 = 0,baseline.txt!D11=-1),"",inter_pl_update.txt!D11 / baseline.txt!D11) | D35: =IF(OR(baseline.txt!H11 = 0,baseline.txt!H11=-1),"",inter_pl_update.txt!H11 / baseline.txt!H11) | E35: =IF(OR(baseline.txt!J11 = 0,baseline.txt!J11=-1),"",inter_pl_update.txt!J11 / baseline.txt!J11) | F35: =IF(OR(baseline.txt!L11 = 0,baseline.txt!L11=-1),"",inter_pl_update.txt!L11 / baseline.txt!L11) | G35: =IF(OR(baseline.txt!M11 = 0,baseline.txt!M11=-1),"",inter_pl_update.txt!M11 / baseline.txt!M11) | H35: =IF(OR(baseline.txt!S11 = 0,baseline.txt!S11=-1),"",inter_pl_update.txt!S11 / baseline.txt!S11) | I35: =IF(OR(baseline.txt!U11 = 0,baseline.txt!U11=-1),"",inter_pl_update.txt!U11 / baseline.txt!U11) | J35: =IF(OR(baseline.txt!V11 = 0,baseline.txt!V11=-1),"",inter_pl_update.txt!V11 / baseline.txt!V11) | K35: =IF(OR(baseline.txt!AD11 = 0,baseline.txt!AD11=-1),"",inter_pl_update.txt!AD11 / baseline.txt!AD11) | L35: =IF(OR(baseline.txt!AH11 = 0,baseline.txt!AH11=-1),"",inter_pl_update.txt!AH11 / baseline.txt!AH11) | M35: =IF(OR(baseline.txt!AK11 = 0,baseline.txt!AK11=-1),"",inter_pl_update.txt!AK11 / baseline.txt!AK11) | N35: =IF(OR(baseline.txt!AN11 = 0,baseline.txt!AN11=-1),"",inter_pl_update.txt!AN11 / baseline.txt!AN11) | O35: =IF(OR(baseline.txt!AR11 = 0,baseline.txt!AR11=-1),"",inter_pl_update.txt!AR11 / baseline.txt!AR11) | P35: =IF(OR(baseline.txt!AT11 = 0,baseline.txt!AT11=-1),"",inter_pl_update.txt!AT11 / baseline.txt!AT11) | Q35: =IF(OR(baseline.txt!AZ11 = 0,baseline.txt!AZ11=-1),"",inter_pl_update.txt!AZ11 / baseline.txt!AZ11) | R35: =IF(OR(baseline.txt!BC11 = 0,baseline.txt!BC11=-1),"",inter_pl_update.txt!BC11 / baseline.txt!BC11) | S35: =IF(OR(baseline.txt!BP11 = 0,baseline.txt!BP11=-1),"",inter_pl_update.txt!BP11 / baseline.txt!BP11) | T35: =IF(OR(baseline.txt!CF11 = 0,baseline.txt!CF11=-1),"",inter_pl_update.txt!CF11 / baseline.txt!CF11) | U35: =IF(OR(baseline.txt!CG11 = 0,baseline.txt!CG11=-1),"",inter_pl_update.txt!CG11 / baseline.txt!CG11) | V35: =IF(OR(baseline.txt!CP11 = 0,baseline.txt!CP11=-1),"",inter_pl_update.txt!CP11 / baseline.txt!CP11)
A36: =baseline.txt!A12 | B36: =baseline.txt!B12 | C36: =IF(OR(baseline.txt!D12 = 0,baseline.txt!D12=-1),"",inter_pl_update.txt!D12 / baseline.txt!D12) | D36: =IF(OR(baseline.txt!H12 = 0,baseline.txt!H12=-1),"",inter_pl_update.txt!H12 / baseline.txt!H12) | E36: =IF(OR(baseline.txt!J12 = 0,baseline.txt!J12=-1),"",inter_pl_update.txt!J12 / baseline.txt!J12) | F36: =IF(OR(baseline.txt!L12 = 0,baseline.txt!L12=-1),"",inter_pl_update.txt!L12 / baseline.txt!L12) | G36: =IF(OR(baseline.txt!M12 = 0,baseline.txt!M12=-1),"",inter_pl_update.txt!M12 / baseline.txt!M12) | H36: =IF(OR(baseline.txt!S12 = 0,baseline.txt!S12=-1),"",inter_pl_update.txt!S12 / baseline.txt!S12) | I36: =IF(OR(baseline.txt!U12 = 0,baseline.txt!U12=-1),"",inter_pl_update.txt!U12 / baseline.txt!U12) | J36: =IF(OR(baseline.txt!V12 = 0,baseline.txt!V12=-1),"",inter_pl_update.txt!V12 / baseline.txt!V12) | K36: =IF(OR(baseline.txt!AD12 = 0,baseline.txt!AD12=-1),"",inter_pl_update.txt!AD12 / baseline.txt!AD12) | L36: =IF(OR(baseline.txt!AH12 = 0,baseline.txt!AH12=-1),"",inter_pl_update.txt!AH12 / baseline.txt!AH12) | M36: =IF(OR(baseline.txt!AK12 = 0,baseline.txt!AK12=-1),"",inter_pl_update.txt!AK12 / baseline.txt!AK12) | N36: =IF(OR(baseline.txt!AN12 = 0,baseline.txt!AN12=-1),"",inter_pl_update.txt!AN12 / baseline.txt!AN12) | O36: =IF(OR(baseline.txt!AR12 = 0,baseline.txt!AR12=-1),"",inter_pl_update.txt!AR12 / baseline.txt!AR12) | P36: =IF(OR(baseline.txt!AT12 = 0,baseline.txt!AT12=-1),"",inter_pl_update.txt!AT12 / baseline.txt!AT12) | Q36: =IF(OR(baseline.txt!AZ12 = 0,baseline.txt!AZ12=-1),"",inter_pl_update.txt!AZ12 / baseline.txt!AZ12) | R36: =IF(OR(baseline.txt!BC12 = 0,baseline.txt!BC12=-1),"",inter_pl_update.txt!BC12 / baseline.txt!BC12) | S36: =IF(OR(baseline.txt!BP12 = 0,baseline.txt!BP12=-1),"",inter_pl_update.txt!BP12 / baseline.txt!BP12) | T36: =IF(OR(baseline.txt!CF12 = 0,baseline.txt!CF12=-1),"",inter_pl_update.txt!CF12 / baseline.txt!CF12) | U36: =IF(OR(baseline.txt!CG12 = 0,baseline.txt!CG12=-1),"",inter_pl_update.txt!CG12 / baseline.txt!CG12) | V36: =IF(OR(baseline.txt!CP12 = 0,baseline.txt!CP12=-1),"",inter_pl_update.txt!CP12 / baseline.txt!CP12)
A37: =baseline.txt!A13 | B37: =baseline.txt!B13 | C37: =IF(OR(baseline.txt!D13 = 0,baseline.txt!D13=-1),"",inter_pl_update.txt!D13 / baseline.txt!D13) | D37: =IF(OR(baseline.txt!H13 = 0,baseline.txt!H13=-1),"",inter_pl_update.txt!H13 / baseline.txt!H13) | E37: =IF(OR(baseline.txt!J13 = 0,baseline.txt!J13=-1),"",inter_pl_update.txt!J13 / baseline.txt!J13) | F37: =IF(OR(baseline.txt!L13 = 0,baseline.txt!L13=-1),"",inter_pl_update.txt!L13 / baseline.txt!L13) | G37: =IF(OR(baseline.txt!M13 = 0,baseline.txt!M13=-1),"",inter_pl_update.txt!M13 / baseline.txt!M13) | H37: =IF(OR(baseline.txt!S13 = 0,baseline.txt!S13=-1),"",inter_pl_update.txt!S13 / baseline.txt!S13) | I37: =IF(OR(baseline.txt!U13 = 0,baseline.txt!U13=-1),"",inter_pl_update.txt!U13 / baseline.txt!U13) | J37: =IF(OR(baseline.txt!V13 = 0,baseline.txt!V13=-1),"",inter_pl_update.txt!V13 / baseline.txt!V13) | K37: =IF(OR(baseline.txt!AD13 = 0,baseline.txt!AD13=-1),"",inter_pl_update.txt!AD13 / baseline.txt!AD13) | L37: =IF(OR(baseline.txt!AH13 = 0,baseline.txt!AH13=-1),"",inter_pl_update.txt!AH13 / baseline.txt!AH13) | M37: =IF(OR(baseline.txt!AK13 = 0,baseline.txt!AK13=-1),"",inter_pl_update.txt!AK13 / baseline.txt!AK13) | N37: =IF(OR(baseline.txt!AN13 = 0,baseline.txt!AN13=-1),"",inter_pl_update.txt!AN13 / baseline.txt!AN13) | O37: =IF(OR(baseline.txt!AR13 = 0,baseline.txt!AR13=-1),"",inter_pl_update.txt!AR13 / baseline.txt!AR13) | P37: =IF(OR(baseline.txt!AT13 = 0,baseline.txt!AT13=-1),"",inter_pl_update.txt!AT13 / baseline.txt!AT13) | Q37: =IF(OR(baseline.txt!AZ13 = 0,baseline.txt!AZ13=-1),"",inter_pl_update.txt!AZ13 / baseline.txt!AZ13) | R37: =IF(OR(baseline.txt!BC13 = 0,baseline.txt!BC13=-1),"",inter_pl_update.txt!BC13 / baseline.txt!BC13) | S37: =IF(OR(baseline.txt!BP13 = 0,baseline.txt!BP13=-1),"",inter_pl_update.txt!BP13 / baseline.txt!BP13) | T37: =IF(OR(baseline.txt!CF13 = 0,baseline.txt!CF13=-1),"",inter_pl_update.txt!CF13 / baseline.txt!CF13) | U37: =IF(OR(baseline.txt!CG13 = 0,baseline.txt!CG13=-1),"",inter_pl_update.txt!CG13 / baseline.txt!CG13) | V37: =IF(OR(baseline.txt!CP13 = 0,baseline.txt!CP13=-1),"",inter_pl_update.txt!CP13 / baseline.txt!CP13)
... A44: =baseline.txt!A20 | B44: =baseline.txt!B20 | C44: =IF(OR(baseline.txt!D20 = 0,baseline.txt!D20=-1),"",inter_pl_update.txt!D20 / baseline.txt!D20) | D44: =IF(OR(baseline.txt!H20 = 0,baseline.txt!H20=-1),"",inter_pl_update.txt!H20 / baseline.txt!H20) | E44: =IF(OR(baseline.txt!J20 = 0,baseline.txt!J20=-1),"",inter_pl_update.txt!J20 / baseline.txt!J20) | F44: =IF(OR(baseline.txt!L20 = 0,baseline.txt!L20=-1),"",inter_pl_update.txt!L20 / baseline.txt!L20) | G44: =IF(OR(baseline.txt!M20 = 0,baseline.txt!M20=-1),"",inter_pl_update.txt!M20 / baseline.txt!M20) | H44: =IF(OR(baseline.txt!S20 = 0,baseline.txt!S20=-1),"",inter_pl_update.txt!S20 / baseline.txt!S20) | I44: =IF(OR(baseline.txt!U20 = 0,baseline.txt!U20=-1),"",inter_pl_update.txt!U20 / baseline.txt!U20) | J44: =IF(OR(baseline.txt!V20 = 0,baseline.txt!V20=-1),"",inter_pl_update.txt!V20 / baseline.txt!V20) | K44: =IF(OR(baseline.txt!AD20 = 0,baseline.txt!AD20=-1),"",inter_pl_update.txt!AD20 / baseline.txt!AD20) | L44: =IF(OR(baseline.txt!AH20 = 0,baseline.txt!AH20=-1),"",inter_pl_update.txt!AH20 / baseline.txt!AH20) | M44: =IF(OR(baseline.txt!AK20 = 0,baseline.txt!AK20=-1),"",inter_pl_update.txt!AK20 / baseline.txt!AK20) | N44: =IF(OR(baseline.txt!AN20 = 0,baseline.txt!AN20=-1),"",inter_pl_update.txt!AN20 / baseline.txt!AN20) | O44: =IF(OR(baseline.txt!AR20 = 0,baseline.txt!AR20=-1),"",inter_pl_update.txt!AR20 / baseline.txt!AR20) | P44: =IF(OR(baseline.txt!AT20 = 0,baseline.txt!AT20=-1),"",inter_pl_update.txt!AT20 / baseline.txt!AT20) | Q44: =IF(OR(baseline.txt!AZ20 = 0,baseline.txt!AZ20=-1),"",inter_pl_update.txt!AZ20 / baseline.txt!AZ20) | R44: =IF(OR(baseline.txt!BC20 = 0,baseline.txt!BC20=-1),"",inter_pl_update.txt!BC20 / baseline.txt!BC20) | S44: =IF(OR(baseline.txt!BP20 = 0,baseline.txt!BP20=-1),"",inter_pl_update.txt!BP20 / baseline.txt!BP20) | T44: =IF(OR(baseline.txt!CF20 = 0,baseline.txt!CF20=-1),"",inter_pl_update.txt!CF20 / baseline.txt!CF20) | U44: =IF(OR(baseline.txt!CG20 = 0,baseline.txt!CG20=-1),"",inter_pl_update.txt!CG20 / baseline.txt!CG20) | V44: =IF(OR(baseline.txt!CP20 = 0,baseline.txt!CP20=-1),"",inter_pl_update.txt!CP20 / baseline.txt!CP20)
